Workbook

Sheet 📋 מבוא
B2: שמחות פלוס | BSimchot Plus — תוכנית עסקית מורחבת
B3: עמדות פיזיות דיגיטליות באולמות אירועים: מתנות באשראי, מתנות דיגיטליות ואישורי הגעה (RSVP) | גרסה מורחבת 25/06/2026
B4: הופק: 18/06/2026 | גרסה 1.0
B6: תוכן עניינים
B7: 1. | C7: 📊 סקר שוק - מתחרים | D7: כולל Mazalit; נדרים פלוס מסומן כשותף ולא כמתחרה
B8: 2. | C8: 🏛️ אולמות - רשימה | D8: 342 אולמות וגנים — עיר, אזור, קטגוריה, קהל יעד, מס' אולמות, טלפון, אימייל
B9: 3. | C9: 📈 נתוני שוק | D9: שוק חתונות, ענף האירועים, מחירי מנה ומתנות דיגיטליות
B10: 4. | C10: 📊 מגזרים וסכומי מתנות | D10: פילוח מגזר/תת-מגזר: סכומי מתנה, יתרון העמדה, חבילה בסגירת אולם
B11: 5. | C11: 👥 סקר לקוחות | D11: שאלות וממצאים לבעלי אירועים ואורחים
B12: 6. | C12: 🏢 סקר אולמות B2B | D12: שאלות וממצאים לבעלי אולמות
B13: 7. | C13: 💼 תוכנית עסקית | D13: הנחות קלט כחולות, מודל הכנסות B2B2C ויחידת כלכלה
B14: 8. | C14: 💰 רווח והפסד | D14: מטריצת רווחיות חיה ו-P&L רב-שנתי
B15: 9. | C15: 📉 ניתוח עמדה | D15: רגישות רווחיות לפי מחזור וסליקה
B16: 10. | C16: 🗓️ תחזית 7 שנים | D16: תחזית 2025-2031 עם נוסחאות
B17: 11. | C17: 💡 רעיונות וחדשנות | D17: מפת חדשנות מוצרית עם תעדוף לפי תחום
B18: 12. | C18: 🖥️ ממשק והרחבות | D18: UX לאולמות/אירועים + הרחבה לדינרים, תערוכות ועמדת תצוגה
... B20: 14. | C20: 🔗 מקורות | D20: רשימת מקורות עם URL

Sheet 📊 סקר שוק - מתחרים
B2: סקר מתחרים מורחב | מתנות דיגיטליות, RSVP ועמדות פיזיות בישראל
B3: נדרים פלוס אינו מופיע כמתחרה — הוא שותף סליקה/קהילה פוטנציאלי למודול חרדי. נתונים מבוססים על מקורות ציבוריים שנאספו ביוני 2026.
B5: חברה | C5: סוג שירות | D5: מחיר/הקמה ציבוריים | E5: עמלה/סליקה | F5: עמדה פיזית | G5: לידים לאולם | H5: תנאים/חוזה/פרטי שירות | I5: יתרונות | J5: חסרונות/פערים | K5: מקורות
B6: Easy2Give | C6: מתנות באשראי + RSVP + עמדות/ארנק דיגיטלי | D6: לרוב ללא הקמה למתנה; RSVP לפי רשומה; דיילי הושבה החל 1,450₪ | E6: עמלה משתנה; Mako דיווח על מינימום 6.9₪ ועד 2.7% ודוגמאות סביב 2%+ | F6: כן | G6: לא | H6: מקסימום מתנה 5,000₪; עד 6 תשלומים; העברה תוך כמה ימי עסקים; דוחות מתנות; RSVP חינם מעל מדרגות מתנות | I6: מותג מוכר, עמדות פיזיות, מענה מוכח | J6: עמלות אורח נתפסות כגבוהות; הליד נשאר אצל החברה/הזוג ולא אצל האולם | K6: Easy2Give - תנאי שימוש; Easy2Give - מבצע RSVP 2026; Mako/N12 - עמלות מתנות באשראי
B7: DigitalPick | C7: אישורי הגעה, הושבה ומתנות באשראי | D7: חבילות 650₪, 1,850₪, 2,800₪; חנות: 0.80-1.65₪ לרשומה; מתנות באשראי 200₪ | E7: לא פורסם באתר; השירות כלול/נמכר כחבילה | F7: חלקי/דיגיטלי | G7: לא | H7: וואטסאפ, טלפונים, הושבה, דיילת רישום 999₪, הושבה מלאה 1,300₪ | I7: חבילות ברורות ורחבות, שירותי יום אירוע | J7: פחות ממוקד בעמדה פיזית ייעודית; אין מודל לידים לאולם | K7: DigitalPick - אתר וחבילות; DigitalPick - חנות אונליין; DigitalPick - Mit4Mit
B8: MyInvite | C8: הזמנות דיגיטליות, RSVP ומתנות באשראי | D8: 0₪/149₪/199₪/299₪ לפי גודל אירוע; ביטול מתנות מחזיר למחיר 1.8₪ לרשומה | E8: 5.8% + מע״מ = 6.84% מבעלי האירוע; 8₪ עמלת טיפול לאורח לעסקה | F8: לא | G8: לא | H8: כסף מועבר ב-5 או ב-11 לחודש העוקב לפי תאריך האירוע; חובה בחלק מהחבילות | I8: מחיר כניסה נמוך, All-in-One פשוט | J8: עמלה גבוהה לבעלי האירוע; ללא עמדה פיזית; אין לידים לאולם | K8: MyInvite - מתנות באשראי ותקנון; MyInvite - מחיר RSVP; MyInvite - Mit4Mit
B9: DIGINET | C9: הזמנות דיגיטליות, RSVP, הושבה ומתנות באשראי | D9: מתנות באשראי 100₪ במקום 250₪ או חינם בשדרוג; Mit4Mit מחיר ממוצע 726₪ | E9: לא פורסם; הכסף מתקבל במלואו לפי האתר | F9: לא | G9: לא | H9: Apple Pay/Google Pay; עד 6 תשלומים; העברת כספים עד 3 ימי עסקים החל מיומיים אחרי האירוע | I9: מוצר דיגיטלי מודרני, אפליקציה, חבילות שדרוג | J9: פחות בידול בעמדה פיזית; תלות בוואטסאפ/דיגיטל | K9: DIGINET - חבילות ומחירים; DIGINET - מתנות באשראי; DIGINET - Mit4Mit
B10: Wedix | C10: אפליקציה/לינק למתנות באשראי והזמנות | D10: משתנה לפי מספר הודעות ושירותים; אין מחיר אחיד באתר | E10: עמלות אורח/עלות שירות לפי חבילה | F10: לא | G10: לא | H10: שירות מתנה דרך אפליקציה/לינק; מצוין שאינו דומה לעמדות פיזיות באירועים | I10: מוצר תוכן/דיגיטל ממוקד חתונות | J10: ללא עמדה פיזית; מחיר לא שקוף | K10: Wedix - מתנות באשראי; Wedix - יתרונות וחסרונות
B11: Attending | C11: פלטפורמת ניהול אירוע, RSVP, הזמנות AI ומתנות באשראי | D11: אישורי הגעה וואטסאפ/SMS החל 199₪; טלפוני החל 199₪; הזמנה דיגיטלית החל 129₪ | E11: לא פורסם בפירוט | F11: לא | G11: לא | H11: הקמת אירוע תוך דקות, הודעות, מתנות אשראי, הושבה, סנכרון בזמן אמת | I11: UI מודרני, מחיר כניסה נמוך, מיקוד RSVP | J11: אין עמדה פיזית/כספת דיגיטלית באולם; אין ערך שיווקי מובנה לאולם | K11: Attending - אתר; Attending - מחירים
B12: MagiimOlo / מגיעים או לא | C12: אישורי הגעה מנוהלים עם מוקד אנושי, SMS/WhatsApp | D12: מינימום הזמנה 200₪ למסלול SMS ו-300₪ למסלול WhatsApp; מחיר לפי רשומות | E12: לא רלוונטי/לא מפורסם למתנות | F12: לא | G12: לא | H12: מוקד אנושי, 4 סבבי SMS או 2 סבבי WhatsApp, דגש על דיוק הגעה וחיסכון מנות | I12: שירות אנושי ותיק, חיסכון במנות | J12: לא פתרון מתנות באשראי מלא; ללא עמדה ולידים לאולם | K12: MagiimOlo - מחירון
B13: Mazalit / מזל״ט | C13: עמדות מתנות אשראי לציבור החרדי | D13: לא פורסם; מותאם לקהלים נפרדים באולם | E13: לא פורסם; הפעלה דרך נש״פ/RSVP לפי התקנון | F13: כן — עמדות גברים/נשים | G13: לא | H13: עמדות פיזיות באולם; קישור לאנשים שלא הגיעו; סגירת קישור בבוקר למחרת; העברה תוך עד 7 ימי עסקים; בנוי לציבור החרדי | I13: מענה כשר/חרדי, עמדה פיזית ותהליך אמון | J13: נישה מגזרית; מחיר לא שקוף; ללא מודול לידים לאולם | K13: Mazalit - תקנון; Mazalit - אתר
B14: שמחות פלוס (Benchmark) | C14: עמדה פיזית + מתנות אשראי + RSVP + דף נחיתה ולידים לאולם | D14: 100-200₪ דמי הקמה לאירוע + 50₪ חשבון סליקה | E14: 0.5%-1% הכנסה; יעד מחיר נגיש מול השוק | F14: כן — מלא | G14: כן — בידול עיקרי | H14: B2B2C: האולם מוכר, בעל האירוע משלם, האולם מקבל לידים חמים ו-White Label | I14: מודל לידים ייחודי, עמדה פיזית, מחיר נמוך, הכנסה מרובדת | J14: דרוש אמון, פריסה תפעולית והתקנות בשטח | K14: פרמטרים שסופקו על ידי היזם
B17: מקורות: Mako/N12 - עמלות מתנות באשראי, Mazalit - תקנון, MyInvite - מתנות באשראי ותקנון, DIGINET - חבילות ומחירים

Sheet 🏛️ אולמות - רשימה
B2: מיפוי אולמות וגני אירועים בישראל — רשימת יעד מכירות B2B2C
B3: 342 מקומות מכל הארץ, מסווגים לפי עיר, אזור, קטגוריה, קהל יעד ומספר אולמות במתחם. נתוני קיבולת/טלפון/אימייל מבוססים מקורות ציבוריים — יש לאמת טלפונית לפני פנייה מסחרית. תאים ריקים = נתון לא פורסם.
B5: סיכום לפי קטגוריה (מתעדכן אוטומטית)
B6: קטגוריה | C6: מספר מקומות
B7: אולם חתונות גדול | C7: =COUNTIF($F$17:$F$358,B7) -> 72
B8: גן אירועים | C8: =COUNTIF($F$17:$F$358,B8) -> 99
B9: אולם קטן/בוטיק | C9: =COUNTIF($F$17:$F$358,B9) -> 68
B10: מתחם רב-אולמי | C10: =COUNTIF($F$17:$F$358,B10) -> 23
B11: לופט/אורבני | C11: =COUNTIF($F$17:$F$358,B11) -> 29
B12: אולם בבית כנסת/קהילתי | C12: =COUNTIF($F$17:$F$358,B12) -> 6
B13: מקום מיוחד (חוף/וילה/טבע) | C13: =COUNTIF($F$17:$F$358,B13) -> 45
B14: סה"כ | C14: =COUNTA($B$17:$B$358) -> 342
B16: # | C16: שם המקום | D16: עיר | E16: אזור | F16: קטגוריה | G16: קיבולת (מוזמנים) | H16: קהל יעד | I16: מס' אולמות במתחם | J16: טלפון | K16: אימייל | L16: קישור/מקור | M16: עדיפות פנייה
B17: 1 | C17: הרמוניה בגן | D17: גדרה | E17: שפלה | F17: גן אירועים | I17: 1 | J17: 07-23926890 | L17: https://www.mit4mit.co.il | M17: =IF(OR(E17="אולם חתונות גדול",E17="מתחם רב-אולמי",I17>=2,D17="מרכז",D17="שרון",D17="ירושלים והסביבה"),"גבוה","בינוני") -> בינוני
B18: 2 | C18: חוות אלנבי | D18: נצר סרני | E18: מרכז | F18: מקום מיוחד (חוף/וילה/טבע) | I18: 1 | J18: 050-8090777 | L18: https://www.mit4mit.co.il | M18: =IF(OR(E18="אולם חתונות גדול",E18="מתחם רב-אולמי",I18>=2,D18="מרכז",D18="שרון",D18="ירושלים והסביבה"),"גבוה","בינוני") -> בינוני
B19: 3 | C19: אלגריה | D19: קרית עקרון | E19: שפלה | F19: גן אירועים | I19: 1 | J19: 07-23926805 | L19: https://www.mit4mit.co.il | M19: =IF(OR(E19="אולם חתונות גדול",E19="מתחם רב-אולמי",I19>=2,D19="מרכז",D19="שרון",D19="ירושלים והסביבה"),"גבוה","בינוני") -> בינוני
B20: 4 | C20: חוות דרך ארץ | D20: מושב מחסיה | E20: ירושלים והסביבה | F20: מקום מיוחד (חוף/וילה/טבע) | I20: 1 | J20: 052-6845559 | L20: https://www.mit4mit.co.il | M20: =IF(OR(E20="אולם חתונות גדול",E20="מתחם רב-אולמי",I20>=2,D20="מרכז",D20="שרון",D20="ירושלים והסביבה"),"גבוה","בינוני") -> בינוני
B21: 5 | C21: וילה נונה | D21: קיסריה | E21: שרון | F21: מקום מיוחד (חוף/וילה/טבע) | H21: כללי | I21: 1 | J21: 050-8090158 | L21: https://www.mit4mit.co.il | M21: =IF(OR(E21="אולם חתונות גדול",E21="מתחם רב-אולמי",I21>=2,D21="מרכז",D21="שרון",D21="ירושלים והסביבה"),"גבוה","בינוני") -> בינוני
B22: 6 | C22: סרה גן אירועים SERA | D22: בית שמש | E22: ירושלים והסביבה | F22: גן אירועים | G22: 1000 | H22: כללי | I22: 1 | J22: 07-72305479 | L22: https://www.mit4mit.co.il | M22: =IF(OR(E22="אולם חתונות גדול",E22="מתחם רב-אולמי",I22>=2,D22="מרכז",D22="שרון",D22="ירושלים והסביבה"),"גבוה","בינוני") -> בינוני
B23: 7 | C23: גארדן הוטל Garden Hotel | D23: חיפה | E23: צפון | F23: גן אירועים | G23: 300 | H23: כללי | I23: 1 | J23: 050-8355552 | L23: https://www.mit4mit.co.il | M23: =IF(OR(E23="אולם חתונות גדול",E23="מתחם רב-אולמי",I23>=2,D23="מרכז",D23="שרון",D23="ירושלים והסביבה"),"גבוה","בינוני") -> בינוני
B24: 8 | C24: צל החורש | D24: דרום השרון | E24: שרון | F24: גן אירועים | I24: 1 | J24: 07-23971545 | L24: https://www.tzhelhahoresh.co.il | M24: =IF(OR(E24="אולם חתונות גדול",E24="מתחם רב-אולמי",I24>=2,D24="מרכז",D24="שרון",D24="ירושלים והסביבה"),"גבוה","בינוני") -> בינוני
B25: 9 | C25: אודאון גן אירועים בשרון | D25: עמק חפר | E25: שרון | F25: גן אירועים | I25: 1 | J25: 07-23926877 | L25: https://www.mit4mit.co.il | M25: =IF(OR(E25="אולם חתונות גדול",E25="מתחם רב-אולמי",I25>=2,D25="מרכז",D25="שרון",D25="ירושלים והסביבה"),"גבוה","בינוני") -> בינוני
B26: 10 | C26: 88 גן אירועים | D26: עמק חפר | E26: שרון | F26: גן אירועים | I26: 1 | J26: 07-23726878 | L26: https://www.mit4mit.co.il | M26: =IF(OR(E26="אולם חתונות גדול",E26="מתחם רב-אולמי",I26>=2,D26="מרכז",D26="שרון",D26="ירושלים והסביבה"),"גבוה","בינוני") -> בינוני
B27: 11 | C27: אגדתא | D27: בני ראם | E27: שפלה | F27: מתחם רב-אולמי | H27: כללי | I27: 2 | J27: 07-23971539 | L27: https://www.mit4mit.co.il | M27: =IF(OR(E27="אולם חתונות גדול",E27="מתחם רב-אולמי",I27>=2,D27="מרכז",D27="שרון",D27="ירושלים והסביבה"),"גבוה","בינוני") -> גבוה
B28: 12 | C28: 58 גן ומתחם אירועים | D28: פתח תקווה | E28: מרכז | F28: גן אירועים | I28: 1 | J28: 055-9705798 | L28: https://www.mit4mit.co.il | M28: =IF(OR(E28="אולם חתונות גדול",E28="מתחם רב-אולמי",I28>=2,D28="מרכז",D28="שרון",D28="ירושלים והסביבה"),"גבוה","בינוני") -> בינוני
B29: 13 | C29: שמורתה גן אירועים | D29: אפק | E29: שרון | F29: גן אירועים | I29: 1 | J29: 07-23932938 | L29: https://www.mit4mit.co.il | M29: =IF(OR(E29="אולם חתונות גדול",E29="מתחם רב-אולמי",I29>=2,D29="מרכז",D29="שרון",D29="ירושלים והסביבה"),"גבוה","בינוני") -> בינוני
B30: 14 | C30: קיסר ים | D30: קיסריה | E30: שרון | F30: מקום מיוחד (חוף/וילה/טבע) | I30: 1 | J30: 050-8090170 | L30: https://www.mit4mit.co.il | M30: =IF(OR(E30="אולם חתונות גדול",E30="מתחם רב-אולמי",I30>=2,D30="מרכז",D30="שרון",D30="ירושלים והסביבה"),"גבוה","בינוני") -> בינוני
B31: 15 | C31: קויה מתחם אירועים | D31: חולון | E31: מרכז | F31: מתחם רב-אולמי | I31: 1 | J31: 055-9705807 | L31: https://www.mit4mit.co.il | M31: =IF(OR(E31="אולם חתונות גדול",E31="מתחם רב-אולמי",I31>=2,D31="מרכז",D31="שרון",D31="ירושלים והסביבה"),"גבוה","בינוני") -> בינוני
B32: 16 | C32: חלום בחווה | D32: חדרה | E32: שרון | F32: מקום מיוחד (חוף/וילה/טבע) | I32: 1 | J32: 07-23926883 | L32: https://www.mit4mit.co.il | M32: =IF(OR(E32="אולם חתונות גדול",E32="מתחם רב-אולמי",I32>=2,D32="מרכז",D32="שרון",D32="ירושלים והסביבה"),"גבוה","בינוני") -> בינוני
B33: 17 | C33: ים YAM | D33: תל אביב-יפו | E33: מרכז | F33: מקום מיוחד (חוף/וילה/טבע) | I33: 1 | J33: 055-2118726 | L33: https://www.mit4mit.co.il | M33: =IF(OR(E33="אולם חתונות גדול",E33="מתחם רב-אולמי",I33>=2,D33="מרכז",D33="שרון",D33="ירושלים והסביבה"),"גבוה","בינוני") -> בינוני
B34: 18 | C34: עלמה | D34: אבן יהודה | E34: שרון | F34: גן אירועים | I34: 1 | J34: 050-8005552 | L34: https://www.mit4mit.co.il | M34: =IF(OR(E34="אולם חתונות גדול",E34="מתחם רב-אולמי",I34>=2,D34="מרכז",D34="שרון",D34="ירושלים והסביבה"),"גבוה","בינוני") -> בינוני
B35: 19 | C35: הגבעה | D35: גבעת ברנר | E35: מרכז | F35: גן אירועים | I35: 1 | J35: 050-8005550 | L35: https://www.mit4mit.co.il | M35: =IF(OR(E35="אולם חתונות גדול",E35="מתחם רב-אולמי",I35>=2,D35="מרכז",D35="שרון",D35="ירושלים והסביבה"),"גבוה","בינוני") -> בינוני
B36: 20 | C36: White | D36: פרדס חנה-כרכור | E36: שרון | F36: אולם קטן/בוטיק | I36: 1 | J36: 07-23926806 | L36: https://www.mit4mit.co.il | M36: =IF(OR(E36="אולם חתונות גדול",E36="מתחם רב-אולמי",I36>=2,D36="מרכז",D36="שרון",D36="ירושלים והסביבה"),"גבוה","בינוני") -> בינוני
B37: 21 | C37: בית חלל אירועים אורבני | D37: רעננה | E37: שרון | F37: לופט/אורבני | G37: 450 | H37: כללי | I37: 1 | J37: 050-8090783 | L37: https://www.mit4mit.co.il | M37: =IF(OR(E37="אולם חתונות גדול",E37="מתחם רב-אולמי",I37>=2,D37="מרכז",D37="שרון",D37="ירושלים והסביבה"),"גבוה","בינוני") -> בינוני
B38: 22 | C38: YARA יארה | D38: חדרה | E38: שרון | F38: גן אירועים | I38: 1 | J38: 055-9705765 | L38: https://www.mit4mit.co.il | M38: =IF(OR(E38="אולם חתונות גדול",E38="מתחם רב-אולמי",I38>=2,D38="מרכז",D38="שרון",D38="ירושלים והסביבה"),"גבוה","בינוני") -> בינוני
B39: 23 | C39: גאיה חדרה | D39: חדרה | E39: שרון | F39: גן אירועים | G39: 800 | H39: כללי | I39: 1 | J39: 07-23939928 | L39: https://www.mit4mit.co.il | M39: =IF(OR(E39="אולם חתונות גדול",E39="מתחם רב-אולמי",I39>=2,D39="מרכז",D39="שרון",D39="ירושלים והסביבה"),"גבוה","בינוני") -> בינוני
B40: 24 | C40: עדן גן האירועים | D40: ניר אליהו | E40: שרון | F40: גן אירועים | I40: 1 | J40: 07-23929931 | L40: https://www.mit4mit.co.il | M40: =IF(OR(E40="אולם חתונות גדול",E40="מתחם רב-אולמי",I40>=2,D40="מרכז",D40="שרון",D40="ירושלים והסביבה"),"גבוה","בינוני") -> בינוני
B41: 25 | C41: שרונית גן אירועים | D41: משמר השרון | E41: שרון | F41: גן אירועים | I41: 1 | J41: 07-23929927 | L41: https://www.mit4mit.co.il | M41: =IF(OR(E41="אולם חתונות גדול",E41="מתחם רב-אולמי",I41>=2,D41="מרכז",D41="שרון",D41="ירושלים והסביבה"),"גבוה","בינוני") -> בינוני
B42: 26 | C42: בורג׳ בנימינה | D42: בנימינה | E42: שרון | F42: מקום מיוחד (חוף/וילה/טבע) | G42: 600 | H42: כללי | I42: 1 | J42: 050-8092044 | L42: https://www.mit4mit.co.il | M42: =IF(OR(E42="אולם חתונות גדול",E42="מתחם רב-אולמי",I42>=2,D42="מרכז",D42="שרון",D42="ירושלים והסביבה"),"גבוה","בינוני") -> בינוני
B43: 27 | C43: ביער גן אירועים | D43: פארק השרון | E43: שרון | F43: מקום מיוחד (חוף/וילה/טבע) | I43: 1 | J43: 07-23932929 | L43: https://www.mit4mit.co.il | M43: =IF(OR(E43="אולם חתונות גדול",E43="מתחם רב-אולמי",I43>=2,D43="מרכז",D43="שרון",D43="ירושלים והסביבה"),"גבוה","בינוני") -> בינוני
...

Sheet 📈 נתוני שוק
B2: נתוני שוק האירועים והחתונות בישראל | 2025-2026
B3: הנתונים משלבים מקורות ציבוריים רשמיים, אתרי ענף וכתבות צרכניות. כל נתון מסומן במקור.
B5: נושא | C5: ממצא/נתון | D5: מקור
B6: היקף נישואין בישראל | C6: 51,643 זוגות נישאו בישראל בשנת 2022; מתוכם 37,135 יהודים, 12,756 מוסלמים, 959 דרוזים, 762 נוצרים | D6: הלמ״ס - נישואין בישראל 2024 PDF
B7: רישום נישואין 2024 | C7: המשרד לשירותי דת דיווח על עלייה של כ-10% במספר הזוגות שנרשמו לנישואין דרך לשכות הנישואין בשנת 2024 | D7: Ynet - רישום נישואין 2024
B8: ענף האולמות | C8: 450 אולמות וגני אירועים מאוגדים; 2 מיליון אורחים בחודש; 17 מיליארד ₪ הכנסות שנתיות; 150 אלף עובדים ישירים | D8: התאחדות האולמות - נתוני ענף
B9: מחיר חתונה ממוצעת 2025 | C9: עלות חתונה ממוצעת בישראל 130-150 אלף ₪ לאירוע סטנדרטי של כ-300 מוזמנים; מחיר מנה 300-400₪ לפי ICE | D9: ICE - עלות חתונה 2025
B10: טווח מחיר מנה 2025 | C10: Mit4Mit מציין טווח מרכז 350-600₪ למנה והפרשי אזור/עונה | D10: Mit4Mit - עלות חתונה 2025
B11: מחירונים אזוריים | C11: B144 מציג: צפון 200-400₪, דרום 250-500₪, מרכז 300-600₪, ירושלים 250-700₪ לחתונה קטנה | D11: B144 - מחירון אולמות
B12: עמלות מתנות באשראי | C12: Mako/N12 דיווח על עמלות מתנה באשראי של 2% ואף יותר; דוגמה 15.5₪ למתנה של 500₪; בעל האירוע משלם לרוב כ-200₪ לשירות | D12: Mako/N12 - עמלות מתנות באשראי
B13: טרנד דיגיטלי | C13: שירותים מובילים מציעים מתנות בכרטיס אשראי, Apple Pay/Google Pay, RSVP בוואטסאפ/SMS והעברות לאחר האירוע | D13: DIGINET - מתנות באשראי; Attending - אתר; Easy2Give - אודות מתנות באשראי
B14: תובנת מוצר | C14: עמדה פיזית באולם יכולה לגשר על הפער בין אורח שלא פתח לינק לבין צורך מיידי בכניסה לאולם | D14: ניתוח שמחות פלוס
B15: מתנה ממוצעת | C15: הנחת המודל: 400₪ ללא עמדה לעומת 550₪ עם עמדת אשראי (+37.5%) | D15: פרמטרים שסופקו על ידי היזם
B18: טבלת חישוב TAM/SAM/SOM
B19: מדד | C19: נוסחה/הנחה | D19: ערך
B20: אולמות וגנים מאוגדים | C20: נתון התאחדות | D20: 450
B21: חדירה אפשרית ל-50% מהשוק | C21: D20*50% | D21: =D20*50% -> 225
B22: אירועים ממוצע לאולם לחודש | C22: הנחת מודל | D22: 26
B23: עמדות יעד לחדירה 50% | C23: D21 | D23: =D21 -> 225
B24: מחזור מתנות לעמדה/חודש | C24: C28*C27 מתוכנית עסקית | D24: ='💼 תוכנית עסקית'!C27*'💼 תוכנית עסקית'!C28 -> 112500

Sheet 📊 מגזרים וסכומי מתנות
B2: סקר שוק לפי מגזרים — סכומי מתנות, יתרון העמדה וחבילה בסגירת אולם
B3: פילוח מגזר/תת-מגזר עם טווחי מתנה משוערים (אומדני שוק/כתבות), יתרון עמדת האשראי בכל מגזר, ואופן שילוב החבילה כחלק מסגירת האולם. אומדני מתנה דורשים אימות בסקר שטח.
B5: מגזר | C5: תת-מגזר | D5: סוג אירוע נפוץ | E5: מתנה ממוצעת (ללא עמדה) ₪ | F5: מתנה ממוצעת (עם עמדת אשראי) ₪ | G5: גידול % | H5: יתרון העמדה במגזר | I5: חבילה בסגירת אולם
B6: חילוני | C6: מרכז/ת"א | D6: חתונה | E6: 450 | F6: 620 | G6: =IF(E6>0,(F6-E6)/E6,"") -> 0.37777778 | H6: נוחות ומיידיות; אורח צעיר רגיל לאשראי/Apple Pay | I6: כלול אוטומטית בחבילת אולם פרימיום
B7: חילוני | C7: פריפריה | D7: חתונה | E7: 350 | F7: 470 | G7: =IF(E7>0,(F7-E7)/E7,"") -> 0.34285714 | H7: חוסך מזומן/צ'קים; פריסה לתשלומים מגדילה מתנה | I7: תוספת מומלצת בעת סגירת תאריך
B8: חילוני | C8: אירוע קטן/בוטיק | D8: אירוסין/יום הולדת | E8: 300 | F8: 400 | G8: =IF(E8>0,(F8-E8)/E8,"") -> 0.33333333 | H8: עמדה קומפקטית; חוויה אישית | I8: חבילת בוטיק מוזלת
B9: דתי-לאומי | C9: מרכז ושפלה | D9: חתונה | E9: 450 | F9: 600 | G9: =IF(E9>0,(F9-E9)/E9,"") -> 0.33333333 | H9: מקובל ומוכר; משלב ברכה/מזכרת | I9: ברירת מחדל בחבילת אולם דתי
B10: דתי-לאומי | C10: ירושלים והסביבה | D10: חתונה | E10: 480 | F10: 640 | G10: =IF(E10>0,(F10-E10)/E10,"") -> 0.33333333 | H10: קהל גדול → ערך מצטבר גבוה | I10: כלול בחבילה + מסלול תרומה לישיבות
B11: חרדי | C11: ליטאי/חסידי | D11: חתונה | E11: 350 | F11: 500 | G11: =IF(E11>0,(F11-E11)/E11,"") -> 0.42857143 | H11: מסלול כשר IVR/ללא סמארטפון; הפרדת עמדות | I11: מודול כשר נפרד; שותפות נדרים פלוס
B12: חרדי | C12: ספרדי | D12: חתונה | E12: 380 | F12: 520 | G12: =IF(E12>0,(F12-E12)/E12,"") -> 0.36842105 | H12: אמון דרך גורם קהילתי; עמלה שקופה | I12: חבילה עם הכשר/אישור גורם מוכר
B13: מסורתי/מעורב | C13: דרום ואשדוד | D13: חתונה | E13: 380 | F13: 520 | G13: =IF(E13>0,(F13-E13)/E13,"") -> 0.36842105 | H13: גישור על העדפת מזומן בעזרת נוחות | I13: תוספת בעת סגירת אולם
B14: מגזר ערבי | C14: צפון ומשולש | D14: חתונה גדולה | E14: 300 | F14: 430 | G14: =IF(E14>0,(F14-E14)/E14,"") -> 0.43333333 | H14: אירועים גדולים מאוד; פוטנציאל נפח | I14: פיילוט ייעודי + ממשק בערבית
B15: עמותות/מלכ"ר | C15: ארצי | D15: דינר התרמה | E15: לא רלוונטי | F15: תרומה/מכירה | G15: — | H15: עמדת תרומה + קבלה 46א' + יעד חי | I15: מנוי שנתי / חבילת אירועי התרמה
B16: עסקי/B2B | C16: ארצי | D16: כנס/תערוכה | E16: לא רלוונטי | F16: תרומה/מכירה | G16: — | H16: עמדת תצוגה ולידים + תשלום כניסה/מוצר | I16: דמי הקמה לאירוע + עמלת מכירה
B18: אסטרטגיית 'חבילה בסגירת אולם'
B19: • המודל: בעל האירוע סוגר אולם → שמחות פלוס כבר מובנית בחבילה (לא מכירה נפרדת). חוסך חיכוך מכירה.
B20: • האולם מציג את השירות כ'ערך מוסף שלו' — מתנה דיגיטלית, RSVP ודוחות — ומחזק את סגירת העסקה.
B21: • בעל האירוע משלם (100-200₪ דמי הקמה); האולם לא נושא בעלות ומקבל לידים חמים — Win-Win-Win (B2B2C).
B22: • תאי הסכום בכחול ניתנים לעריכה; עמודת הגידול מחושבת אוטומטית בנוסחה.

Sheet 👥 סקר לקוחות
B2: סקר שוק לקוחות | בעלי אירועים ואורחים
B3: גיליון זה משלב שאלות לסקר עתידי עם ממצאים ממקורות שוק זמינים על חתונות ומתנות דיגיטליות.
B5: נושא | C5: שאלת סקר מומלצת | D5: ממצא שוק | E5: השלכה למוצר | F5: מקור
B6: אופן מתן מתנה מועדף | C6: איזו דרך היית מעדיף/ה למתנה: מזומן/צ׳ק/Bit/כרטיס אשראי בעמדה/קישור? | D6: פער בין נוחות דיגיטלית לבין חשש מעמלות; Mako הציף רגישות גבוהה לעמלה באשראי | E6: להציע עמדה בלי עמלה לאורח או עמלה שקופה ונמוכה | F6: Mako/N12 - עמלות מתנות באשראי
B7: ממוצע מתנה | C7: מה סכום המתנה הממוצע שלך לאירוע? | D7: הנחת מודל: 400₪ ללא עמדה מול 550₪ עם אשראי (+37.5%) | E7: להציג לבעל אירוע את הגדלת המתנה כ-ROI ישיר | F7: פרמטרים שסופקו על ידי היזם
B8: נכונות לשלם דמי שירות | C8: האם היית משלם/ת 100-200₪ לאירוע עבור ניהול מתנות, RSVP ודוחות? | D8: Mako מציין שבדרך כלל בעלי אירוע משלמים כ-200₪ לשירות מתנות/דוחות | E8: תמחור 100-200₪ תחרותי מול השוק | F8: Mako/N12 - עמלות מתנות באשראי
B9: חסם עיקרי | C9: מה ימנע ממך להשתמש בעמדת אשראי? עמלה, פרטיות, תור, תקלה, חוסר אמון? | D9: חסמי אמון ועמלה הם המרכזיים בשירותים פיננסיים לאירוע | E9: להדגיש אבטחת סליקה, נש״פ/שותף פיננסי, דוח מיידי ושירות במקום | F9: Mako/N12 - עמלות מתנות באשראי; Mazalit - תקנון
B10: תשלומים | C10: האם האפשרות לפרוס מתנה לתשלומים תגדיל את הסכום? | D10: Easy2Give ותחרות מציעים עד 6 תשלומים; זה מצדיק עמלה אך עלול לעורר התנגדות | E10: לאפשר תשלומים אך להציג סכום כולל/עמלה בצורה ברורה | F10: Easy2Give - תנאי שימוש; DIGINET - מתנות באשראי
B11: קישור מול עמדה | C11: האם תשתמש/י בקישור שנשלח ביום האירוע או בעמדה בכניסה? | D11: לינק דיגיטלי נוח אך לא תמיד נפתח בזמן; עמדה פיזית תופסת רגע כוונה גבוה | E11: לשלב קישור + עמדה כדי למקסם המרה | F11: DIGINET - מתנות באשראי; Easy2Give - אודות מתנות באשראי
B12: ציבור חרדי | C12: האם נדרשת הפרדה/עמדות נשים-גברים או תהליך ללא סמארטפון? | D12: Mazalit מציגה עמדות נפרדות ובנייה לציבור החרדי | E12: מודול כשר/חרדי עם IVR ושותף נדרים פלוס כמסלול עתידי | F12: Mazalit - תקנון
B13: שקיפות ודוחות | C13: איזה דוח תרצה לקבל אחרי האירוע? | D13: מתחרים מציעים דוח מתנות, ברכות וסיכומים לאחר האירוע | E13: דוח בזמן אמת + יצוא Excel + התאמת שם אורח לרשומת RSVP | F13: Easy2Give - אודות מתנות באשראי; MyInvite - מתנות באשראי ותקנון

Sheet 🏢 סקר אולמות B2B
B2: סקר שוק אולמות | בעלי אולמות, מנהלי מכירות ושיווק
B3: מיקוד B2B: מה יגרום לאולם לאמץ עמדה שמייצרת ערך לבעל האירוע וגם לידים חמים לאולם.
B5: נושא | C5: שאלה לבעלי אולמות | D5: תובנה | E5: החלטת מוצר/מכירה
B6: לידים חמים | C6: האם תיתן שירות חינם/מומלץ אם תקבל לידים של אורחים שמתעניינים באירוע עתידי? | D6: הזדמנות בידול: אף מתחרה שנבדק לא מציע לידים לאולם כערך מרכזי | E6: זהו מסר המכירה הראשי לבעל אולם
B7: עלות לאולם | C7: האם תאמץ פתרון אם בעל האירוע משלם והאולם לא נושא בעלות? | D7: מודל B2B2C מפחית חסם אימוץ ומאפשר לאולם להציג שירות חדש | E7: לא להעמיס על מחיר המנה; לשלב בחבילת אירוע
B8: אמינות תפעולית | C8: מה SLA נדרש ביום אירוע? | D8: עמדה פיזית באירוע קריטי דורשת תמיכה, גיבוי אינטרנט/חשמל וניהול תור | E8: חובה ערכת גיבוי וסקר תפעולי לכל אולם
B9: מיתוג | C9: האם חשוב שההזמנה/דף נחיתה יהיו במיתוג האולם? | D9: White Label מגדיל נכס שיווקי והופך כל הזמנה למדיה של האולם | E9: לפתח עורך דף נחיתה לכל אולם
B10: דאטה ובעלות לידים | C10: איזה מידע מותר וחשוב לקבל? | D10: חייבים הסכמה מפורשת ושמירת פרטיות; ערך גבוה אם הדאטה נקי ומסווג | E10: טופס הסכמה + CRM + תיוג אירוע
B11: קהל חרדי/מסורתי | C11: האם יש אירועים הדורשים מסלול כשר/ללא סמארטפון? | D11: Mazalit מוכיחה צורך במגזר חרדי עם עמדות נפרדות; נדרים פלוס עשוי להיות שותף, לא מתחרה | E11: להציע מסלול כשר + IVR
B12: מדדי הצלחה | C12: אילו KPI ישכנעו אותך להמשיך? | D12: מספר לידים, שיעור המרה, הכנסה עקיפה, שביעות רצון זוגות, אפס תקלות | E12: דשבורד מנהל אולם עם KPI ברורים
B13: אינטגרציות | C13: האם נדרשת אינטגרציה ל-CRM/ניהול אולם? | D13: אולמות גדולים יעדיפו חיבור למערכות קיימות | E13: API/CSV בשלב ראשון; אינטגרציה מלאה בשלב צמיחה
B16: מקורות: התאחדות האולמות - נתוני ענף, Mazalit - תקנון, ניתוח שמחות פלוס

Sheet 💼 תוכנית עסקית
B2: תוכנית עסקית | הנחות, מודל הכנסות ויחידת כלכלה
B3: תאי קלט בצבע כחול. נוסחאות חיות מאפשרות שינוי הנחות וניתוח מיידי.
B7: פרמטר | C7: ערך | D7: יחידה | E7: סוג
B8: עלות הקמת עמדה (חומרה+התקנה) | C8: 3500 | D8: ₪ | E8: קלט
B9: שירות חודשי לעמדה | C9: 200 | D9: ₪/חודש | E9: קלט
B10: הקמת חשבון סליקה לאירוע | C10: 50 | D10: ₪ + מע״מ | E10: קלט
B11: דמי הקמה לאירוע - נמוך | C11: 100 | D11: ₪ | E11: קלט
B12: דמי הקמה לאירוע - גבוה | C12: 200 | D12: ₪ | E12: קלט
B13: דמי הקמה ממוצעים לאירוע | C13: =AVERAGE(C11:C12) -> 150 | D13: ₪ | E13: נוסחה
B14: עמלת סליקה הכנסה - נמוך | C14: 0.005 | D14: % | E14: קלט
B15: עמלת סליקה הכנסה - גבוה | C15: 0.01 | D15: % | E15: קלט
B16: עמלת סליקה ממוצעת | C16: =AVERAGE(C14:C15) -> 0.0075 | D16: % | E16: נוסחה
B17: מתנה ממוצעת ללא עמדה | C17: 400 | D17: ₪ | E17: קלט
B18: מתנה ממוצעת עם עמדת אשראי | C18: 550 | D18: ₪ | E18: קלט
B19: שיפור מתנה ממוצעת | C19: =C18/C17-1 -> 0.375 | D19: % | E19: נוסחה
B20: הוצאות חודשיות קבועות | C20: 24500 | D20: ₪/חודש | E20: קלט
B21: השקעת פיתוח שכבר הוצאה | C21: 100000
B22: תקציב פרסום | C22: 50000 | D22: ₪ | E22: קלט
B23: הוצאות נלוות | C23: 50000 | D23: ₪ | E23: קלט
B24: סה״כ השקעה ראשונית | C24: =SUM(C21:C23) -> 200000 | D24: ₪ | E24: נוסחה
B25: מספר אורחים ממוצע לאירוע | C25: 250 | D25: אורחים | E25: קלט
B26: שיעור אורחים שנותנים באשראי בעמדה | C26: 0.18 | D26: % | E26: קלט
B27: מחזור סליקה ממוצע לאירוע | C27: 22500 | D27: ₪ | E27: קלט
B28: אירועים לחודש לעמדה | C28: 5 | D28: אירועים | E28: קלט
B29: הכנסה ממוצעת לאירוע | C29: =C10+C13+C27*C16 -> 368.75 | D29: ₪ | E29: נוסחה
B30: רווח גולמי לעמדה/חודש | C30: =C29*C28-C9 -> 1643.75
B31: נקודת איזון עמדות | C31: =ROUNDUP(C20/C30,0) -> 15 | D31: עמדות | E31: נוסחה
B37: מודל B2B2C
B38: צד במודל | C38: ערך עסקי
B39: אולם | C39: מוכר/ממליץ על השירות כחלק מחבילת האירוע; מקבל דף נחיתה ממותג ולידים חמים
B40: בעל האירוע | C40: משלם דמי הקמה/שירות ומקבל ניהול מתנות + RSVP + דוחות בזמן אמת
B41: אורחים | C41: נותנים מתנה באשראי בעמדה פיזית או בקישור דיגיטלי, עם אפשרות ברכה ותשלומים
B42: שמחות פלוס | C42: מרוויחה מדמי הקמה, עמלת סליקה ושירות חודשי לעמדה
B45: מקורות: פרמטרים שסופקו על ידי היזם, התאחדות האולמות - נתוני ענף, Mako/N12 - עמלות מתנות באשראי

Sheet 💰 רווח והפסד
B2: דוח רווח והפסד | מטריצת רווחיות ותחזית לפי מספר עמדות
B3: כל התאים במטריצות משתמשים בנוסחאות חיות מתוך גיליון תוכנית עסקית.
B5: חלק א׳: רווח גולמי חודשי לעמדה לפי אירועים ומחזור סליקה
B6: מחזור לאירוע | C6: 1 | D6: 2 | E6: 3 | F6: 4 | G6: 5 | H6: 6 | I6: 7 | J6: 8 | K6: 9 | L6: 10
B7: 10000 | C7: =(C$6*('💼 תוכנית עסקית'!$C$10+'💼 תוכנית עסקית'!$C$13+$B7*'💼 תוכנית עסקית'!$C$16))-'💼 תוכנית עסקית'!$C$9 -> 75 | D7: =(D$6*('💼 תוכנית עסקית'!$C$10+'💼 תוכנית עסקית'!$C$13+$B7*'💼 תוכנית עסקית'!$C$16))-'💼 תוכנית עסקית'!$C$9 -> 350 | E7: =(E$6*('💼 תוכנית עסקית'!$C$10+'💼 תוכנית עסקית'!$C$13+$B7*'💼 תוכנית עסקית'!$C$16))-'💼 תוכנית עסקית'!$C$9 -> 625 | F7: =(F$6*('💼 תוכנית עסקית'!$C$10+'💼 תוכנית עסקית'!$C$13+$B7*'💼 תוכנית עסקית'!$C$16))-'💼 תוכנית עסקית'!$C$9 -> 900 | G7: =(G$6*('💼 תוכנית עסקית'!$C$10+'💼 תוכנית עסקית'!$C$13+$B7*'💼 תוכנית עסקית'!$C$16))-'💼 תוכנית עסקית'!$C$9 -> 1175 | H7: =(H$6*('💼 תוכנית עסקית'!$C$10+'💼 תוכנית עסקית'!$C$13+$B7*'💼 תוכנית עסקית'!$C$16))-'💼 תוכנית עסקית'!$C$9 -> 1450 | I7: =(I$6*('💼 תוכנית עסקית'!$C$10+'💼 תוכנית עסקית'!$C$13+$B7*'💼 תוכנית עסקית'!$C$16))-'💼 תוכנית עסקית'!$C$9 -> 1725 | J7: =(J$6*('💼 תוכנית עסקית'!$C$10+'💼 תוכנית עסקית'!$C$13+$B7*'💼 תוכנית עסקית'!$C$16))-'💼 תוכנית עסקית'!$C$9 -> 2000 | ... L7: =(L$6*('💼 תוכנית עסקית'!$C$10+'💼 תוכנית עסקית'!$C$13+$B7*'💼 תוכנית עסקית'!$C$16))-'💼 תוכנית עסקית'!$C$9 -> 2550
B8: 12500 | C8: =(C$6*('💼 תוכנית עסקית'!$C$10+'💼 תוכנית עסקית'!$C$13+$B8*'💼 תוכנית עסקית'!$C$16))-'💼 תוכנית עסקית'!$C$9 -> 93.75 | D8: =(D$6*('💼 תוכנית עסקית'!$C$10+'💼 תוכנית עסקית'!$C$13+$B8*'💼 תוכנית עסקית'!$C$16))-'💼 תוכנית עסקית'!$C$9 -> 387.5 | E8: =(E$6*('💼 תוכנית עסקית'!$C$10+'💼 תוכנית עסקית'!$C$13+$B8*'💼 תוכנית עסקית'!$C$16))-'💼 תוכנית עסקית'!$C$9 -> 681.25 | F8: =(F$6*('💼 תוכנית עסקית'!$C$10+'💼 תוכנית עסקית'!$C$13+$B8*'💼 תוכנית עסקית'!$C$16))-'💼 תוכנית עסקית'!$C$9 -> 975 | G8: =(G$6*('💼 תוכנית עסקית'!$C$10+'💼 תוכנית עסקית'!$C$13+$B8*'💼 תוכנית עסקית'!$C$16))-'💼 תוכנית עסקית'!$C$9 -> 1268.75 | H8: =(H$6*('💼 תוכנית עסקית'!$C$10+'💼 תוכנית עסקית'!$C$13+$B8*'💼 תוכנית עסקית'!$C$16))-'💼 תוכנית עסקית'!$C$9 -> 1562.5 | I8: =(I$6*('💼 תוכנית עסקית'!$C$10+'💼 תוכנית עסקית'!$C$13+$B8*'💼 תוכנית עסקית'!$C$16))-'💼 תוכנית עסקית'!$C$9 -> 1856.25 | J8: =(J$6*('💼 תוכנית עסקית'!$C$10+'💼 תוכנית עסקית'!$C$13+$B8*'💼 תוכנית עסקית'!$C$16))-'💼 תוכנית עסקית'!$C$9 -> 2150 | ... L8: =(L$6*('💼 תוכנית עסקית'!$C$10+'💼 תוכנית עסקית'!$C$13+$B8*'💼 תוכנית עסקית'!$C$16))-'💼 תוכנית עסקית'!$C$9 -> 2737.5
B9: 15000 | C9: =(C$6*('💼 תוכנית עסקית'!$C$10+'💼 תוכנית עסקית'!$C$13+$B9*'💼 תוכנית עסקית'!$C$16))-'💼 תוכנית עסקית'!$C$9 -> 112.5 | D9: =(D$6*('💼 תוכנית עסקית'!$C$10+'💼 תוכנית עסקית'!$C$13+$B9*'💼 תוכנית עסקית'!$C$16))-'💼 תוכנית עסקית'!$C$9 -> 425 | E9: =(E$6*('💼 תוכנית עסקית'!$C$10+'💼 תוכנית עסקית'!$C$13+$B9*'💼 תוכנית עסקית'!$C$16))-'💼 תוכנית עסקית'!$C$9 -> 737.5 | F9: =(F$6*('💼 תוכנית עסקית'!$C$10+'💼 תוכנית עסקית'!$C$13+$B9*'💼 תוכנית עסקית'!$C$16))-'💼 תוכנית עסקית'!$C$9 -> 1050 | G9: =(G$6*('💼 תוכנית עסקית'!$C$10+'💼 תוכנית עסקית'!$C$13+$B9*'💼 תוכנית עסקית'!$C$16))-'💼 תוכנית עסקית'!$C$9 -> 1362.5 | H9: =(H$6*('💼 תוכנית עסקית'!$C$10+'💼 תוכנית עסקית'!$C$13+$B9*'💼 תוכנית עסקית'!$C$16))-'💼 תוכנית עסקית'!$C$9 -> 1675 | I9: =(I$6*('💼 תוכנית עסקית'!$C$10+'💼 תוכנית עסקית'!$C$13+$B9*'💼 תוכנית עסקית'!$C$16))-'💼 תוכנית עסקית'!$C$9 -> 1987.5 | J9: =(J$6*('💼 תוכנית עסקית'!$C$10+'💼 תוכנית עסקית'!$C$13+$B9*'💼 תוכנית עסקית'!$C$16))-'💼 תוכנית עסקית'!$C$9 -> 2300 | ... L9: =(L$6*('💼 תוכנית עסקית'!$C$10+'💼 תוכנית עסקית'!$C$13+$B9*'💼 תוכנית עסקית'!$C$16))-'💼 תוכנית עסקית'!$C$9 -> 2925
B10: 17500 | C10: =(C$6*('💼 תוכנית עסקית'!$C$10+'💼 תוכנית עסקית'!$C$13+$B10*'💼 תוכנית עסקית'!$C$16))-'💼 תוכנית עסקית'!$C$9 -> 131.25 | D10: =(D$6*('💼 תוכנית עסקית'!$C$10+'💼 תוכנית עסקית'!$C$13+$B10*'💼 תוכנית עסקית'!$C$16))-'💼 תוכנית עסקית'!$C$9 -> 462.5 | E10: =(E$6*('💼 תוכנית עסקית'!$C$10+'💼 תוכנית עסקית'!$C$13+$B10*'💼 תוכנית עסקית'!$C$16))-'💼 תוכנית עסקית'!$C$9 -> 793.75 | F10: =(F$6*('💼 תוכנית עסקית'!$C$10+'💼 תוכנית עסקית'!$C$13+$B10*'💼 תוכנית עסקית'!$C$16))-'💼 תוכנית עסקית'!$C$9 -> 1125 | G10: =(G$6*('💼 תוכנית עסקית'!$C$10+'💼 תוכנית עסקית'!$C$13+$B10*'💼 תוכנית עסקית'!$C$16))-'💼 תוכנית עסקית'!$C$9 -> 1456.25 | H10: =(H$6*('💼 תוכנית עסקית'!$C$10+'💼 תוכנית עסקית'!$C$13+$B10*'💼 תוכנית עסקית'!$C$16))-'💼 תוכנית עסקית'!$C$9 -> 1787.5 | I10: =(I$6*('💼 תוכנית עסקית'!$C$10+'💼 תוכנית עסקית'!$C$13+$B10*'💼 תוכנית עסקית'!$C$16))-'💼 תוכנית עסקית'!$C$9 -> 2118.75 | J10: =(J$6*('💼 תוכנית עסקית'!$C$10+'💼 תוכנית עסקית'!$C$13+$B10*'💼 תוכנית עסקית'!$C$16))-'💼 תוכנית עסקית'!$C$9 -> 2450 | ... L10: =(L$6*('💼 תוכנית עסקית'!$C$10+'💼 תוכנית עסקית'!$C$13+$B10*'💼 תוכנית עסקית'!$C$16))-'💼 תוכנית עסקית'!$C$9 -> 3112.5
B11: 20000 | C11: =(C$6*('💼 תוכנית עסקית'!$C$10+'💼 תוכנית עסקית'!$C$13+$B11*'💼 תוכנית עסקית'!$C$16))-'💼 תוכנית עסקית'!$C$9 -> 150 | D11: =(D$6*('💼 תוכנית עסקית'!$C$10+'💼 תוכנית עסקית'!$C$13+$B11*'💼 תוכנית עסקית'!$C$16))-'💼 תוכנית עסקית'!$C$9 -> 500 | E11: =(E$6*('💼 תוכנית עסקית'!$C$10+'💼 תוכנית עסקית'!$C$13+$B11*'💼 תוכנית עסקית'!$C$16))-'💼 תוכנית עסקית'!$C$9 -> 850 | F11: =(F$6*('💼 תוכנית עסקית'!$C$10+'💼 תוכנית עסקית'!$C$13+$B11*'💼 תוכנית עסקית'!$C$16))-'💼 תוכנית עסקית'!$C$9 -> 1200 | G11: =(G$6*('💼 תוכנית עסקית'!$C$10+'💼 תוכנית עסקית'!$C$13+$B11*'💼 תוכנית עסקית'!$C$16))-'💼 תוכנית עסקית'!$C$9 -> 1550 | H11: =(H$6*('💼 תוכנית עסקית'!$C$10+'💼 תוכנית עסקית'!$C$13+$B11*'💼 תוכנית עסקית'!$C$16))-'💼 תוכנית עסקית'!$C$9 -> 1900 | I11: =(I$6*('💼 תוכנית עסקית'!$C$10+'💼 תוכנית עסקית'!$C$13+$B11*'💼 תוכנית עסקית'!$C$16))-'💼 תוכנית עסקית'!$C$9 -> 2250 | J11: =(J$6*('💼 תוכנית עסקית'!$C$10+'💼 תוכנית עסקית'!$C$13+$B11*'💼 תוכנית עסקית'!$C$16))-'💼 תוכנית עסקית'!$C$9 -> 2600 | ... L11: =(L$6*('💼 תוכנית עסקית'!$C$10+'💼 תוכנית עסקית'!$C$13+$B11*'💼 תוכנית עסקית'!$C$16))-'💼 תוכנית עסקית'!$C$9 -> 3300
B12: 22500 | C12: =(C$6*('💼 תוכנית עסקית'!$C$10+'💼 תוכנית עסקית'!$C$13+$B12*'💼 תוכנית עסקית'!$C$16))-'💼 תוכנית עסקית'!$C$9 -> 168.75 | D12: =(D$6*('💼 תוכנית עסקית'!$C$10+'💼 תוכנית עסקית'!$C$13+$B12*'💼 תוכנית עסקית'!$C$16))-'💼 תוכנית עסקית'!$C$9 -> 537.5 | E12: =(E$6*('💼 תוכנית עסקית'!$C$10+'💼 תוכנית עסקית'!$C$13+$B12*'💼 תוכנית עסקית'!$C$16))-'💼 תוכנית עסקית'!$C$9 -> 906.25 | F12: =(F$6*('💼 תוכנית עסקית'!$C$10+'💼 תוכנית עסקית'!$C$13+$B12*'💼 תוכנית עסקית'!$C$16))-'💼 תוכנית עסקית'!$C$9 -> 1275 | G12: =(G$6*('💼 תוכנית עסקית'!$C$10+'💼 תוכנית עסקית'!$C$13+$B12*'💼 תוכנית עסקית'!$C$16))-'💼 תוכנית עסקית'!$C$9 -> 1643.75 | H12: =(H$6*('💼 תוכנית עסקית'!$C$10+'💼 תוכנית עסקית'!$C$13+$B12*'💼 תוכנית עסקית'!$C$16))-'💼 תוכנית עסקית'!$C$9 -> 2012.5 | I12: =(I$6*('💼 תוכנית עסקית'!$C$10+'💼 תוכנית עסקית'!$C$13+$B12*'💼 תוכנית עסקית'!$C$16))-'💼 תוכנית עסקית'!$C$9 -> 2381.25 | J12: =(J$6*('💼 תוכנית עסקית'!$C$10+'💼 תוכנית עסקית'!$C$13+$B12*'💼 תוכנית עסקית'!$C$16))-'💼 תוכנית עסקית'!$C$9 -> 2750 | ... L12: =(L$6*('💼 תוכנית עסקית'!$C$10+'💼 תוכנית עסקית'!$C$13+$B12*'💼 תוכנית עסקית'!$C$16))-'💼 תוכנית עסקית'!$C$9 -> 3487.5
B13: 25000 | C13: =(C$6*('💼 תוכנית עסקית'!$C$10+'💼 תוכנית עסקית'!$C$13+$B13*'💼 תוכנית עסקית'!$C$16))-'💼 תוכנית עסקית'!$C$9 -> 187.5 | D13: =(D$6*('💼 תוכנית עסקית'!$C$10+'💼 תוכנית עסקית'!$C$13+$B13*'💼 תוכנית עסקית'!$C$16))-'💼 תוכנית עסקית'!$C$9 -> 575 | E13: =(E$6*('💼 תוכנית עסקית'!$C$10+'💼 תוכנית עסקית'!$C$13+$B13*'💼 תוכנית עסקית'!$C$16))-'💼 תוכנית עסקית'!$C$9 -> 962.5 | F13: =(F$6*('💼 תוכנית עסקית'!$C$10+'💼 תוכנית עסקית'!$C$13+$B13*'💼 תוכנית עסקית'!$C$16))-'💼 תוכנית עסקית'!$C$9 -> 1350 | G13: =(G$6*('💼 תוכנית עסקית'!$C$10+'💼 תוכנית עסקית'!$C$13+$B13*'💼 תוכנית עסקית'!$C$16))-'💼 תוכנית עסקית'!$C$9 -> 1737.5 | H13: =(H$6*('💼 תוכנית עסקית'!$C$10+'💼 תוכנית עסקית'!$C$13+$B13*'💼 תוכנית עסקית'!$C$16))-'💼 תוכנית עסקית'!$C$9 -> 2125 | I13: =(I$6*('💼 תוכנית עסקית'!$C$10+'💼 תוכנית עסקית'!$C$13+$B13*'💼 תוכנית עסקית'!$C$16))-'💼 תוכנית עסקית'!$C$9 -> 2512.5 | J13: =(J$6*('💼 תוכנית עסקית'!$C$10+'💼 תוכנית עסקית'!$C$13+$B13*'💼 תוכנית עסקית'!$C$16))-'💼 תוכנית עסקית'!$C$9 -> 2900 | ... L13: =(L$6*('💼 תוכנית עסקית'!$C$10+'💼 תוכנית עסקית'!$C$13+$B13*'💼 תוכנית עסקית'!$C$16))-'💼 תוכנית עסקית'!$C$9 -> 3675
B14: 30000 | C14: =(C$6*('💼 תוכנית עסקית'!$C$10+'💼 תוכנית עסקית'!$C$13+$B14*'💼 תוכנית עסקית'!$C$16))-'💼 תוכנית עסקית'!$C$9 -> 225 | D14: =(D$6*('💼 תוכנית עסקית'!$C$10+'💼 תוכנית עסקית'!$C$13+$B14*'💼 תוכנית עסקית'!$C$16))-'💼 תוכנית עסקית'!$C$9 -> 650 | E14: =(E$6*('💼 תוכנית עסקית'!$C$10+'💼 תוכנית עסקית'!$C$13+$B14*'💼 תוכנית עסקית'!$C$16))-'💼 תוכנית עסקית'!$C$9 -> 1075 | F14: =(F$6*('💼 תוכנית עסקית'!$C$10+'💼 תוכנית עסקית'!$C$13+$B14*'💼 תוכנית עסקית'!$C$16))-'💼 תוכנית עסקית'!$C$9 -> 1500 | G14: =(G$6*('💼 תוכנית עסקית'!$C$10+'💼 תוכנית עסקית'!$C$13+$B14*'💼 תוכנית עסקית'!$C$16))-'💼 תוכנית עסקית'!$C$9 -> 1925 | H14: =(H$6*('💼 תוכנית עסקית'!$C$10+'💼 תוכנית עסקית'!$C$13+$B14*'💼 תוכנית עסקית'!$C$16))-'💼 תוכנית עסקית'!$C$9 -> 2350 | I14: =(I$6*('💼 תוכנית עסקית'!$C$10+'💼 תוכנית עסקית'!$C$13+$B14*'💼 תוכנית עסקית'!$C$16))-'💼 תוכנית עסקית'!$C$9 -> 2775 | J14: =(J$6*('💼 תוכנית עסקית'!$C$10+'💼 תוכנית עסקית'!$C$13+$B14*'💼 תוכנית עסקית'!$C$16))-'💼 תוכנית עסקית'!$C$9 -> 3200 | ... L14: =(L$6*('💼 תוכנית עסקית'!$C$10+'💼 תוכנית עסקית'!$C$13+$B14*'💼 תוכנית עסקית'!$C$16))-'💼 תוכנית עסקית'!$C$9 -> 4050
B15: 35000 | C15: =(C$6*('💼 תוכנית עסקית'!$C$10+'💼 תוכנית עסקית'!$C$13+$B15*'💼 תוכנית עסקית'!$C$16))-'💼 תוכנית עסקית'!$C$9 -> 262.5 | D15: =(D$6*('💼 תוכנית עסקית'!$C$10+'💼 תוכנית עסקית'!$C$13+$B15*'💼 תוכנית עסקית'!$C$16))-'💼 תוכנית עסקית'!$C$9 -> 725 | E15: =(E$6*('💼 תוכנית עסקית'!$C$10+'💼 תוכנית עסקית'!$C$13+$B15*'💼 תוכנית עסקית'!$C$16))-'💼 תוכנית עסקית'!$C$9 -> 1187.5 | F15: =(F$6*('💼 תוכנית עסקית'!$C$10+'💼 תוכנית עסקית'!$C$13+$B15*'💼 תוכנית עסקית'!$C$16))-'💼 תוכנית עסקית'!$C$9 -> 1650 | G15: =(G$6*('💼 תוכנית עסקית'!$C$10+'💼 תוכנית עסקית'!$C$13+$B15*'💼 תוכנית עסקית'!$C$16))-'💼 תוכנית עסקית'!$C$9 -> 2112.5 | H15: =(H$6*('💼 תוכנית עסקית'!$C$10+'💼 תוכנית עסקית'!$C$13+$B15*'💼 תוכנית עסקית'!$C$16))-'💼 תוכנית עסקית'!$C$9 -> 2575 | I15: =(I$6*('💼 תוכנית עסקית'!$C$10+'💼 תוכנית עסקית'!$C$13+$B15*'💼 תוכנית עסקית'!$C$16))-'💼 תוכנית עסקית'!$C$9 -> 3037.5 | J15: =(J$6*('💼 תוכנית עסקית'!$C$10+'💼 תוכנית עסקית'!$C$13+$B15*'💼 תוכנית עסקית'!$C$16))-'💼 תוכנית עסקית'!$C$9 -> 3500 | ... L15: =(L$6*('💼 תוכנית עסקית'!$C$10+'💼 תוכנית עסקית'!$C$13+$B15*'💼 תוכנית עסקית'!$C$16))-'💼 תוכנית עסקית'!$C$9 -> 4425
B19: חלק ב׳: P&L שנתי לפי תחזית עמדות
B20: שורה | C20: 2025 | D20: 2026 | E20: 2027 | F20: 2028 | G20: 2029 | H20: 2030 | I20: 2031
B21: עמדות בסוף שנה | C21: 5 | D21: 20 | E21: 60 | F21: 120 | G21: 200 | H21: 300 | I21: 450
B22: עמדות ממוצעות פעילות | C22: =C21/2 -> 2.5 | D22: =AVERAGE(C21,D21) -> 12.5 | E22: =AVERAGE(D21,E21) -> 40 | F22: =AVERAGE(E21,F21) -> 90 | G22: =AVERAGE(F21,G21) -> 160 | H22: =AVERAGE(G21,H21) -> 250 | I22: =AVERAGE(H21,I21) -> 375
B23: אירועים/חודש/עמדה | C23: 2 | D23: 3 | E23: 4 | F23: 5 | G23: 5 | H23: 5 | I23: 5
B24: מחזור סליקה/אירוע | C24: ='💼 תוכנית עסקית'!$C$27 -> 22500 | D24: ='💼 תוכנית עסקית'!$C$27 -> 22500 | E24: ='💼 תוכנית עסקית'!$C$27 -> 22500 | F24: ='💼 תוכנית עסקית'!$C$27 -> 22500 | G24: ='💼 תוכנית עסקית'!$C$27 -> 22500 | H24: ='💼 תוכנית עסקית'!$C$27 -> 22500 | I24: ='💼 תוכנית עסקית'!$C$27 -> 22500
B25: הכנסות דמי הקמה+סליקה | C25: =C22*C23*12*('💼 תוכנית עסקית'!$C$10+'💼 תוכנית עסקית'!$C$13+C24*'💼 תוכנית עסקית'!$C$16) -> 22125 | D25: =D22*D23*12*('💼 תוכנית עסקית'!$C$10+'💼 תוכנית עסקית'!$C$13+D24*'💼 תוכנית עסקית'!$C$16) -> 165937.5 | E25: =E22*E23*12*('💼 תוכנית עסקית'!$C$10+'💼 תוכנית עסקית'!$C$13+E24*'💼 תוכנית עסקית'!$C$16) -> 708000 | F25: =F22*F23*12*('💼 תוכנית עסקית'!$C$10+'💼 תוכנית עסקית'!$C$13+F24*'💼 תוכנית עסקית'!$C$16) -> 1991250 | G25: =G22*G23*12*('💼 תוכנית עסקית'!$C$10+'💼 תוכנית עסקית'!$C$13+G24*'💼 תוכנית עסקית'!$C$16) -> 3540000 | H25: =H22*H23*12*('💼 תוכנית עסקית'!$C$10+'💼 תוכנית עסקית'!$C$13+H24*'💼 תוכנית עסקית'!$C$16) -> 5531250 | I25: =I22*I23*12*('💼 תוכנית עסקית'!$C$10+'💼 תוכנית עסקית'!$C$13+I24*'💼 תוכנית עסקית'!$C$16) -> 8296875
B26: הכנסות שירות חודשי | C26: =C22*'💼 תוכנית עסקית'!$C$9*12 -> 6000 | D26: =D22*'💼 תוכנית עסקית'!$C$9*12 -> 30000 | E26: =E22*'💼 תוכנית עסקית'!$C$9*12 -> 96000 | F26: =F22*'💼 תוכנית עסקית'!$C$9*12 -> 216000 | G26: =G22*'💼 תוכנית עסקית'!$C$9*12 -> 384000 | H26: =H22*'💼 תוכנית עסקית'!$C$9*12 -> 600000 | I26: =I22*'💼 תוכנית עסקית'!$C$9*12 -> 900000
B27: סה״כ הכנסות | C27: =SUM(C25:C26) -> 28125 | D27: =SUM(D25:D26) -> 195937.5 | E27: =SUM(E25:E26) -> 804000 | F27: =SUM(F25:F26) -> 2207250 | G27: =SUM(G25:G26) -> 3924000 | H27: =SUM(H25:H26) -> 6131250 | I27: =SUM(I25:I26) -> 9196875
B28: עלות שירות עמדות | C28: =C22*'💼 תוכנית עסקית'!$C$9*12 -> 6000 | D28: =D22*'💼 תוכנית עסקית'!$C$9*12 -> 30000 | E28: =E22*'💼 תוכנית עסקית'!$C$9*12 -> 96000 | F28: =F22*'💼 תוכנית עסקית'!$C$9*12 -> 216000 | G28: =G22*'💼 תוכנית עסקית'!$C$9*12 -> 384000 | H28: =H22*'💼 תוכנית עסקית'!$C$9*12 -> 600000 | I28: =I22*'💼 תוכנית עסקית'!$C$9*12 -> 900000
B29: הוצאות קבועות | C29: ='💼 תוכנית עסקית'!$C$20*12 -> 294000 | D29: ='💼 תוכנית עסקית'!$C$20*12 -> 294000 | E29: ='💼 תוכנית עסקית'!$C$20*12 -> 294000 | F29: ='💼 תוכנית עסקית'!$C$20*12 -> 294000 | G29: ='💼 תוכנית עסקית'!$C$20*12 -> 294000 | H29: ='💼 תוכנית עסקית'!$C$20*12 -> 294000 | I29: ='💼 תוכנית עסקית'!$C$20*12 -> 294000
B30: פרסום/מכירות | C30: 50000 | D30: 50000 | E30: 50000 | F30: 75000 | G30: 75000 | H30: 100000 | I30: 100000
B31: רכישת עמדות חדשות | C31: =5*'💼 תוכנית עסקית'!$C$8 -> 17500 | D31: =15*'💼 תוכנית עסקית'!$C$8 -> 52500 | E31: =40*'💼 תוכנית עסקית'!$C$8 -> 140000 | F31: =60*'💼 תוכנית עסקית'!$C$8 -> 210000 | G31: =80*'💼 תוכנית עסקית'!$C$8 -> 280000 | H31: =100*'💼 תוכנית עסקית'!$C$8 -> 350000 | I31: =150*'💼 תוכנית עסקית'!$C$8 -> 525000
B32: EBITDA | C32: =C27-C28-C29-C30-C31 -> -339375 | D32: =D27-D28-D29-D30-D31 -> -230562.5 | E32: =E27-E28-E29-E30-E31 -> 224000 | F32: =F27-F28-F29-F30-F31 -> 1412250 | G32: =G27-G28-G29-G30-G31 -> 2891000 | H32: =H27-H28-H29-H30-H31 -> 4787250 | I32: =I27-I28-I29-I30-I31 -> 7377875
B33: רווח נקי לפני מס (אומדן) | C33: =C32*0.77 -> -261318.75 | D33: =D32*0.77 -> -177533.12 | E33: =E32*0.77 -> 172480 | F33: =F32*0.77 -> 1087432.5 | G33: =G32*0.77 -> 2226070 | H33: =H32*0.77 -> 3686182.5 | I33: =I32*0.77 -> 5680963.8

Sheet 📉 ניתוח עמדה
B2: ניתוח עמדה | יחידת כלכלה ורגישות
B3: הרווחיות לעמדה מונעת מכמות אירועים, מחזור סליקה לאירוע, עמלת סליקה ודמי הקמה.
B5: מדד | C5: נוסחה | D5: ערך
B6: הכנסה ממוצעת לאירוע | C6: 50₪ + דמי הקמה ממוצעים + מחזור*עמלה | D6: ='💼 תוכנית עסקית'!C29 -> 368.75
B7: רווח גולמי לעמדה/חודש | C7: אירועים*הכנסה לאירוע - שירות חודשי | D7: ='💼 תוכנית עסקית'!C30 -> 1643.75
B8: חודשי החזר עמדה | C8: עלות עמדה / רווח גולמי חודשי | D8: ='💼 תוכנית עסקית'!C8/'💼 תוכנית עסקית'!C30 -> 2.1292776
B9: נקודת איזון עמדות | C9: הוצאות קבועות / רווח גולמי לעמדה | D9: ='💼 תוכנית עסקית'!C31 -> 15
B10: שיפור מתנה ממוצעת | C10: 550/400-1 | D10: ='💼 תוכנית עסקית'!C19 -> 0.375
B13: מטריצת רגישות — רווח גולמי לעמדה/חודש
B14: מחזור סליקה לאירוע | C14: 1 | D14: 2 | E14: 3 | F14: 4 | G14: 5 | H14: 6 | I14: 7 | J14: 8 | K14: 9 | L14: 10
B15: 10000 | C15: =(C$14*('💼 תוכנית עסקית'!$C$10+'💼 תוכנית עסקית'!$C$13+$B15*'💼 תוכנית עסקית'!$C$16))-'💼 תוכנית עסקית'!$C$9 -> 75 | D15: =(D$14*('💼 תוכנית עסקית'!$C$10+'💼 תוכנית עסקית'!$C$13+$B15*'💼 תוכנית עסקית'!$C$16))-'💼 תוכנית עסקית'!$C$9 -> 350 | E15: =(E$14*('💼 תוכנית עסקית'!$C$10+'💼 תוכנית עסקית'!$C$13+$B15*'💼 תוכנית עסקית'!$C$16))-'💼 תוכנית עסקית'!$C$9 -> 625 | F15: =(F$14*('💼 תוכנית עסקית'!$C$10+'💼 תוכנית עסקית'!$C$13+$B15*'💼 תוכנית עסקית'!$C$16))-'💼 תוכנית עסקית'!$C$9 -> 900 | G15: =(G$14*('💼 תוכנית עסקית'!$C$10+'💼 תוכנית עסקית'!$C$13+$B15*'💼 תוכנית עסקית'!$C$16))-'💼 תוכנית עסקית'!$C$9 -> 1175 | H15: =(H$14*('💼 תוכנית עסקית'!$C$10+'💼 תוכנית עסקית'!$C$13+$B15*'💼 תוכנית עסקית'!$C$16))-'💼 תוכנית עסקית'!$C$9 -> 1450 | I15: =(I$14*('💼 תוכנית עסקית'!$C$10+'💼 תוכנית עסקית'!$C$13+$B15*'💼 תוכנית עסקית'!$C$16))-'💼 תוכנית עסקית'!$C$9 -> 1725 | J15: =(J$14*('💼 תוכנית עסקית'!$C$10+'💼 תוכנית עסקית'!$C$13+$B15*'💼 תוכנית עסקית'!$C$16))-'💼 תוכנית עסקית'!$C$9 -> 2000 | ... L15: =(L$14*('💼 תוכנית עסקית'!$C$10+'💼 תוכנית עסקית'!$C$13+$B15*'💼 תוכנית עסקית'!$C$16))-'💼 תוכנית עסקית'!$C$9 -> 2550
B16: 12500 | C16: =(C$14*('💼 תוכנית עסקית'!$C$10+'💼 תוכנית עסקית'!$C$13+$B16*'💼 תוכנית עסקית'!$C$16))-'💼 תוכנית עסקית'!$C$9 -> 93.75 | D16: =(D$14*('💼 תוכנית עסקית'!$C$10+'💼 תוכנית עסקית'!$C$13+$B16*'💼 תוכנית עסקית'!$C$16))-'💼 תוכנית עסקית'!$C$9 -> 387.5 | E16: =(E$14*('💼 תוכנית עסקית'!$C$10+'💼 תוכנית עסקית'!$C$13+$B16*'💼 תוכנית עסקית'!$C$16))-'💼 תוכנית עסקית'!$C$9 -> 681.25 | F16: =(F$14*('💼 תוכנית עסקית'!$C$10+'💼 תוכנית עסקית'!$C$13+$B16*'💼 תוכנית עסקית'!$C$16))-'💼 תוכנית עסקית'!$C$9 -> 975 | G16: =(G$14*('💼 תוכנית עסקית'!$C$10+'💼 תוכנית עסקית'!$C$13+$B16*'💼 תוכנית עסקית'!$C$16))-'💼 תוכנית עסקית'!$C$9 -> 1268.75 | H16: =(H$14*('💼 תוכנית עסקית'!$C$10+'💼 תוכנית עסקית'!$C$13+$B16*'💼 תוכנית עסקית'!$C$16))-'💼 תוכנית עסקית'!$C$9 -> 1562.5 | I16: =(I$14*('💼 תוכנית עסקית'!$C$10+'💼 תוכנית עסקית'!$C$13+$B16*'💼 תוכנית עסקית'!$C$16))-'💼 תוכנית עסקית'!$C$9 -> 1856.25 | J16: =(J$14*('💼 תוכנית עסקית'!$C$10+'💼 תוכנית עסקית'!$C$13+$B16*'💼 תוכנית עסקית'!$C$16))-'💼 תוכנית עסקית'!$C$9 -> 2150 | ... L16: =(L$14*('💼 תוכנית עסקית'!$C$10+'💼 תוכנית עסקית'!$C$13+$B16*'💼 תוכנית עסקית'!$C$16))-'💼 תוכנית עסקית'!$C$9 -> 2737.5
B17: 15000 | C17: =(C$14*('💼 תוכנית עסקית'!$C$10+'💼 תוכנית עסקית'!$C$13+$B17*'💼 תוכנית עסקית'!$C$16))-'💼 תוכנית עסקית'!$C$9 -> 112.5 | D17: =(D$14*('💼 תוכנית עסקית'!$C$10+'💼 תוכנית עסקית'!$C$13+$B17*'💼 תוכנית עסקית'!$C$16))-'💼 תוכנית עסקית'!$C$9 -> 425 | E17: =(E$14*('💼 תוכנית עסקית'!$C$10+'💼 תוכנית עסקית'!$C$13+$B17*'💼 תוכנית עסקית'!$C$16))-'💼 תוכנית עסקית'!$C$9 -> 737.5 | F17: =(F$14*('💼 תוכנית עסקית'!$C$10+'💼 תוכנית עסקית'!$C$13+$B17*'💼 תוכנית עסקית'!$C$16))-'💼 תוכנית עסקית'!$C$9 -> 1050 | G17: =(G$14*('💼 תוכנית עסקית'!$C$10+'💼 תוכנית עסקית'!$C$13+$B17*'💼 תוכנית עסקית'!$C$16))-'💼 תוכנית עסקית'!$C$9 -> 1362.5 | H17: =(H$14*('💼 תוכנית עסקית'!$C$10+'💼 תוכנית עסקית'!$C$13+$B17*'💼 תוכנית עסקית'!$C$16))-'💼 תוכנית עסקית'!$C$9 -> 1675 | I17: =(I$14*('💼 תוכנית עסקית'!$C$10+'💼 תוכנית עסקית'!$C$13+$B17*'💼 תוכנית עסקית'!$C$16))-'💼 תוכנית עסקית'!$C$9 -> 1987.5 | J17: =(J$14*('💼 תוכנית עסקית'!$C$10+'💼 תוכנית עסקית'!$C$13+$B17*'💼 תוכנית עסקית'!$C$16))-'💼 תוכנית עסקית'!$C$9 -> 2300 | ... L17: =(L$14*('💼 תוכנית עסקית'!$C$10+'💼 תוכנית עסקית'!$C$13+$B17*'💼 תוכנית עסקית'!$C$16))-'💼 תוכנית עסקית'!$C$9 -> 2925
B18: 17500 | C18: =(C$14*('💼 תוכנית עסקית'!$C$10+'💼 תוכנית עסקית'!$C$13+$B18*'💼 תוכנית עסקית'!$C$16))-'💼 תוכנית עסקית'!$C$9 -> 131.25 | D18: =(D$14*('💼 תוכנית עסקית'!$C$10+'💼 תוכנית עסקית'!$C$13+$B18*'💼 תוכנית עסקית'!$C$16))-'💼 תוכנית עסקית'!$C$9 -> 462.5 | E18: =(E$14*('💼 תוכנית עסקית'!$C$10+'💼 תוכנית עסקית'!$C$13+$B18*'💼 תוכנית עסקית'!$C$16))-'💼 תוכנית עסקית'!$C$9 -> 793.75 | F18: =(F$14*('💼 תוכנית עסקית'!$C$10+'💼 תוכנית עסקית'!$C$13+$B18*'💼 תוכנית עסקית'!$C$16))-'💼 תוכנית עסקית'!$C$9 -> 1125 | G18: =(G$14*('💼 תוכנית עסקית'!$C$10+'💼 תוכנית עסקית'!$C$13+$B18*'💼 תוכנית עסקית'!$C$16))-'💼 תוכנית עסקית'!$C$9 -> 1456.25 | H18: =(H$14*('💼 תוכנית עסקית'!$C$10+'💼 תוכנית עסקית'!$C$13+$B18*'💼 תוכנית עסקית'!$C$16))-'💼 תוכנית עסקית'!$C$9 -> 1787.5 | I18: =(I$14*('💼 תוכנית עסקית'!$C$10+'💼 תוכנית עסקית'!$C$13+$B18*'💼 תוכנית עסקית'!$C$16))-'💼 תוכנית עסקית'!$C$9 -> 2118.75 | J18: =(J$14*('💼 תוכנית עסקית'!$C$10+'💼 תוכנית עסקית'!$C$13+$B18*'💼 תוכנית עסקית'!$C$16))-'💼 תוכנית עסקית'!$C$9 -> 2450 | ... L18: =(L$14*('💼 תוכנית עסקית'!$C$10+'💼 תוכנית עסקית'!$C$13+$B18*'💼 תוכנית עסקית'!$C$16))-'💼 תוכנית עסקית'!$C$9 -> 3112.5
B19: 20000 | C19: =(C$14*('💼 תוכנית עסקית'!$C$10+'💼 תוכנית עסקית'!$C$13+$B19*'💼 תוכנית עסקית'!$C$16))-'💼 תוכנית עסקית'!$C$9 -> 150 | D19: =(D$14*('💼 תוכנית עסקית'!$C$10+'💼 תוכנית עסקית'!$C$13+$B19*'💼 תוכנית עסקית'!$C$16))-'💼 תוכנית עסקית'!$C$9 -> 500 | E19: =(E$14*('💼 תוכנית עסקית'!$C$10+'💼 תוכנית עסקית'!$C$13+$B19*'💼 תוכנית עסקית'!$C$16))-'💼 תוכנית עסקית'!$C$9 -> 850 | F19: =(F$14*('💼 תוכנית עסקית'!$C$10+'💼 תוכנית עסקית'!$C$13+$B19*'💼 תוכנית עסקית'!$C$16))-'💼 תוכנית עסקית'!$C$9 -> 1200 | G19: =(G$14*('💼 תוכנית עסקית'!$C$10+'💼 תוכנית עסקית'!$C$13+$B19*'💼 תוכנית עסקית'!$C$16))-'💼 תוכנית עסקית'!$C$9 -> 1550 | H19: =(H$14*('💼 תוכנית עסקית'!$C$10+'💼 תוכנית עסקית'!$C$13+$B19*'💼 תוכנית עסקית'!$C$16))-'💼 תוכנית עסקית'!$C$9 -> 1900 | I19: =(I$14*('💼 תוכנית עסקית'!$C$10+'💼 תוכנית עסקית'!$C$13+$B19*'💼 תוכנית עסקית'!$C$16))-'💼 תוכנית עסקית'!$C$9 -> 2250 | J19: =(J$14*('💼 תוכנית עסקית'!$C$10+'💼 תוכנית עסקית'!$C$13+$B19*'💼 תוכנית עסקית'!$C$16))-'💼 תוכנית עסקית'!$C$9 -> 2600 | ... L19: =(L$14*('💼 תוכנית עסקית'!$C$10+'💼 תוכנית עסקית'!$C$13+$B19*'💼 תוכנית עסקית'!$C$16))-'💼 תוכנית עסקית'!$C$9 -> 3300
B20: 22500 | C20: =(C$14*('💼 תוכנית עסקית'!$C$10+'💼 תוכנית עסקית'!$C$13+$B20*'💼 תוכנית עסקית'!$C$16))-'💼 תוכנית עסקית'!$C$9 -> 168.75 | D20: =(D$14*('💼 תוכנית עסקית'!$C$10+'💼 תוכנית עסקית'!$C$13+$B20*'💼 תוכנית עסקית'!$C$16))-'💼 תוכנית עסקית'!$C$9 -> 537.5 | E20: =(E$14*('💼 תוכנית עסקית'!$C$10+'💼 תוכנית עסקית'!$C$13+$B20*'💼 תוכנית עסקית'!$C$16))-'💼 תוכנית עסקית'!$C$9 -> 906.25 | F20: =(F$14*('💼 תוכנית עסקית'!$C$10+'💼 תוכנית עסקית'!$C$13+$B20*'💼 תוכנית עסקית'!$C$16))-'💼 תוכנית עסקית'!$C$9 -> 1275 | G20: =(G$14*('💼 תוכנית עסקית'!$C$10+'💼 תוכנית עסקית'!$C$13+$B20*'💼 תוכנית עסקית'!$C$16))-'💼 תוכנית עסקית'!$C$9 -> 1643.75 | H20: =(H$14*('💼 תוכנית עסקית'!$C$10+'💼 תוכנית עסקית'!$C$13+$B20*'💼 תוכנית עסקית'!$C$16))-'💼 תוכנית עסקית'!$C$9 -> 2012.5 | I20: =(I$14*('💼 תוכנית עסקית'!$C$10+'💼 תוכנית עסקית'!$C$13+$B20*'💼 תוכנית עסקית'!$C$16))-'💼 תוכנית עסקית'!$C$9 -> 2381.25 | J20: =(J$14*('💼 תוכנית עסקית'!$C$10+'💼 תוכנית עסקית'!$C$13+$B20*'💼 תוכנית עסקית'!$C$16))-'💼 תוכנית עסקית'!$C$9 -> 2750 | ... L20: =(L$14*('💼 תוכנית עסקית'!$C$10+'💼 תוכנית עסקית'!$C$13+$B20*'💼 תוכנית עסקית'!$C$16))-'💼 תוכנית עסקית'!$C$9 -> 3487.5
B21: 25000 | C21: =(C$14*('💼 תוכנית עסקית'!$C$10+'💼 תוכנית עסקית'!$C$13+$B21*'💼 תוכנית עסקית'!$C$16))-'💼 תוכנית עסקית'!$C$9 -> 187.5 | D21: =(D$14*('💼 תוכנית עסקית'!$C$10+'💼 תוכנית עסקית'!$C$13+$B21*'💼 תוכנית עסקית'!$C$16))-'💼 תוכנית עסקית'!$C$9 -> 575 | E21: =(E$14*('💼 תוכנית עסקית'!$C$10+'💼 תוכנית עסקית'!$C$13+$B21*'💼 תוכנית עסקית'!$C$16))-'💼 תוכנית עסקית'!$C$9 -> 962.5 | F21: =(F$14*('💼 תוכנית עסקית'!$C$10+'💼 תוכנית עסקית'!$C$13+$B21*'💼 תוכנית עסקית'!$C$16))-'💼 תוכנית עסקית'!$C$9 -> 1350 | G21: =(G$14*('💼 תוכנית עסקית'!$C$10+'💼 תוכנית עסקית'!$C$13+$B21*'💼 תוכנית עסקית'!$C$16))-'💼 תוכנית עסקית'!$C$9 -> 1737.5 | H21: =(H$14*('💼 תוכנית עסקית'!$C$10+'💼 תוכנית עסקית'!$C$13+$B21*'💼 תוכנית עסקית'!$C$16))-'💼 תוכנית עסקית'!$C$9 -> 2125 | I21: =(I$14*('💼 תוכנית עסקית'!$C$10+'💼 תוכנית עסקית'!$C$13+$B21*'💼 תוכנית עסקית'!$C$16))-'💼 תוכנית עסקית'!$C$9 -> 2512.5 | J21: =(J$14*('💼 תוכנית עסקית'!$C$10+'💼 תוכנית עסקית'!$C$13+$B21*'💼 תוכנית עסקית'!$C$16))-'💼 תוכנית עסקית'!$C$9 -> 2900 | ... L21: =(L$14*('💼 תוכנית עסקית'!$C$10+'💼 תוכנית עסקית'!$C$13+$B21*'💼 תוכנית עסקית'!$C$16))-'💼 תוכנית עסקית'!$C$9 -> 3675
B22: 30000 | C22: =(C$14*('💼 תוכנית עסקית'!$C$10+'💼 תוכנית עסקית'!$C$13+$B22*'💼 תוכנית עסקית'!$C$16))-'💼 תוכנית עסקית'!$C$9 -> 225 | D22: =(D$14*('💼 תוכנית עסקית'!$C$10+'💼 תוכנית עסקית'!$C$13+$B22*'💼 תוכנית עסקית'!$C$16))-'💼 תוכנית עסקית'!$C$9 -> 650 | E22: =(E$14*('💼 תוכנית עסקית'!$C$10+'💼 תוכנית עסקית'!$C$13+$B22*'💼 תוכנית עסקית'!$C$16))-'💼 תוכנית עסקית'!$C$9 -> 1075 | F22: =(F$14*('💼 תוכנית עסקית'!$C$10+'💼 תוכנית עסקית'!$C$13+$B22*'💼 תוכנית עסקית'!$C$16))-'💼 תוכנית עסקית'!$C$9 -> 1500 | G22: =(G$14*('💼 תוכנית עסקית'!$C$10+'💼 תוכנית עסקית'!$C$13+$B22*'💼 תוכנית עסקית'!$C$16))-'💼 תוכנית עסקית'!$C$9 -> 1925 | H22: =(H$14*('💼 תוכנית עסקית'!$C$10+'💼 תוכנית עסקית'!$C$13+$B22*'💼 תוכנית עסקית'!$C$16))-'💼 תוכנית עסקית'!$C$9 -> 2350 | I22: =(I$14*('💼 תוכנית עסקית'!$C$10+'💼 תוכנית עסקית'!$C$13+$B22*'💼 תוכנית עסקית'!$C$16))-'💼 תוכנית עסקית'!$C$9 -> 2775 | J22: =(J$14*('💼 תוכנית עסקית'!$C$10+'💼 תוכנית עסקית'!$C$13+$B22*'💼 תוכנית עסקית'!$C$16))-'💼 תוכנית עסקית'!$C$9 -> 3200 | ... L22: =(L$14*('💼 תוכנית עסקית'!$C$10+'💼 תוכנית עסקית'!$C$13+$B22*'💼 תוכנית עסקית'!$C$16))-'💼 תוכנית עסקית'!$C$9 -> 4050
B23: 35000 | C23: =(C$14*('💼 תוכנית עסקית'!$C$10+'💼 תוכנית עסקית'!$C$13+$B23*'💼 תוכנית עסקית'!$C$16))-'💼 תוכנית עסקית'!$C$9 -> 262.5 | D23: =(D$14*('💼 תוכנית עסקית'!$C$10+'💼 תוכנית עסקית'!$C$13+$B23*'💼 תוכנית עסקית'!$C$16))-'💼 תוכנית עסקית'!$C$9 -> 725 | E23: =(E$14*('💼 תוכנית עסקית'!$C$10+'💼 תוכנית עסקית'!$C$13+$B23*'💼 תוכנית עסקית'!$C$16))-'💼 תוכנית עסקית'!$C$9 -> 1187.5 | F23: =(F$14*('💼 תוכנית עסקית'!$C$10+'💼 תוכנית עסקית'!$C$13+$B23*'💼 תוכנית עסקית'!$C$16))-'💼 תוכנית עסקית'!$C$9 -> 1650 | G23: =(G$14*('💼 תוכנית עסקית'!$C$10+'💼 תוכנית עסקית'!$C$13+$B23*'💼 תוכנית עסקית'!$C$16))-'💼 תוכנית עסקית'!$C$9 -> 2112.5 | H23: =(H$14*('💼 תוכנית עסקית'!$C$10+'💼 תוכנית עסקית'!$C$13+$B23*'💼 תוכנית עסקית'!$C$16))-'💼 תוכנית עסקית'!$C$9 -> 2575 | I23: =(I$14*('💼 תוכנית עסקית'!$C$10+'💼 תוכנית עסקית'!$C$13+$B23*'💼 תוכנית עסקית'!$C$16))-'💼 תוכנית עסקית'!$C$9 -> 3037.5 | J23: =(J$14*('💼 תוכנית עסקית'!$C$10+'💼 תוכנית עסקית'!$C$13+$B23*'💼 תוכנית עסקית'!$C$16))-'💼 תוכנית עסקית'!$C$9 -> 3500 | ... L23: =(L$14*('💼 תוכנית עסקית'!$C$10+'💼 תוכנית עסקית'!$C$13+$B23*'💼 תוכנית עסקית'!$C$16))-'💼 תוכנית עסקית'!$C$9 -> 4425

Sheet 🗓️ תחזית 7 שנים
B2: תחזית 7 שנים | 2025-2031
B3: תחזית צמיחה מ-5 ל-450 עמדות. כל החישובים נשענים על ההנחות בגיליון תוכנית עסקית.
B5: מדד
B6: עמדות מותקנות סוף שנה | C6: 5 | D6: 20 | E6: 60 | F6: 120 | G6: 200 | H6: 300 | I6: 450
B7: עמדות חדשות | C7: 5 | D7: =D6-C6 -> 15 | E7: =E6-D6 -> 40 | F7: =F6-E6 -> 60 | G7: =G6-F6 -> 80 | H7: =H6-G6 -> 100 | I7: =I6-H6 -> 150
B8: חדירה מתוך 450 אולמות מאוגדים | C8: =C6/450 -> 0.011111111 | D8: =D6/450 -> 0.044444444 | E8: =E6/450 -> 0.13333333 | F8: =F6/450 -> 0.26666667 | G8: =G6/450 -> 0.44444444 | H8: =H6/450 -> 0.66666667 | I8: =I6/450 -> 1
B9: אירועים/חודש/עמדה | C9: 2 | D9: 3 | E9: 4 | F9: 5 | G9: 5 | H9: 5 | I9: 5
B10: מחזור סליקה שנתי | C10: =AVERAGE(C6,C6-C7)*C9*12*'💼 תוכנית עסקית'!$C$27 -> 1350000 | D10: =AVERAGE(D6,D6-D7)*D9*12*'💼 תוכנית עסקית'!$C$27 -> 10125000 | E10: =AVERAGE(E6,E6-E7)*E9*12*'💼 תוכנית עסקית'!$C$27 -> 43200000 | F10: =AVERAGE(F6,F6-F7)*F9*12*'💼 תוכנית עסקית'!$C$27 -> 121500000 | G10: =AVERAGE(G6,G6-G7)*G9*12*'💼 תוכנית עסקית'!$C$27 -> 216000000 | H10: =AVERAGE(H6,H6-H7)*H9*12*'💼 תוכנית עסקית'!$C$27 -> 337500000 | I10: =AVERAGE(I6,I6-I7)*I9*12*'💼 תוכנית עסקית'!$C$27 -> 506250000
B11: הכנסות שנתיות | C11: ='💰 רווח והפסד'!C27 -> 28125 | D11: ='💰 רווח והפסד'!D27 -> 195937.5 | E11: ='💰 רווח והפסד'!E27 -> 804000 | F11: ='💰 רווח והפסד'!F27 -> 2207250 | G11: ='💰 רווח והפסד'!G27 -> 3924000 | H11: ='💰 רווח והפסד'!H27 -> 6131250 | I11: ='💰 רווח והפסד'!I27 -> 9196875
B12: EBITDA | C12: ='💰 רווח והפסד'!C32 -> -339375 | D12: ='💰 רווח והפסד'!D32 -> -230562.5 | E12: ='💰 רווח והפסד'!E32 -> 224000 | F12: ='💰 רווח והפסד'!F32 -> 1412250 | G12: ='💰 רווח והפסד'!G32 -> 2891000 | H12: ='💰 רווח והפסד'!H32 -> 4787250 | I12: ='💰 רווח והפסד'!I32 -> 7377875
B13: EBITDA מצטבר | C13: =C12 -> -339375 | D13: =C13+D12 -> -569937.5 | E13: =D13+E12 -> -345937.5 | F13: =E13+F12 -> 1066312.5 | G13: =F13+G12 -> 3957312.5 | H13: =G13+H12 -> 8744562.5 | I13: =H13+I12 -> 16122438
B14: סטטוס | C14: =IF(C12>0,"רווחי","טרום איזון") -> טרום איזון | D14: =IF(D12>0,"רווחי","טרום איזון") -> טרום איזון | E14: =IF(E12>0,"רווחי","טרום איזון") -> רווחי | F14: =IF(F12>0,"רווחי","טרום איזון") -> רווחי | G14: =IF(G12>0,"רווחי","טרום איזון") -> רווחי | H14: =IF(H12>0,"רווחי","טרום איזון") -> רווחי | I14: =IF(I12>0,"רווחי","טרום איזון") -> רווחי

Sheet 💡 רעיונות וחדשנות
B2: רעיונות לשיפור והתקדמות בתחום האירועים
B3: מפת חדשנות מוצרית — מקובץ לפי תחום, עם תיאור, ערך ללקוח/אולם, מורכבות מימוש ועדיפות. נועד לתעדוף roadmap.
B5: תחום | C5: רעיון/פיצ'ר | D5: תיאור קצר | E5: ערך לבעל אירוע | F5: ערך לאולם | G5: מורכבות מימוש | H5: עדיפות
B6: מתנות וסליקה | C6: פריסת מתנה לתשלומים | D6: אפשרות לאורח לפרוס מתנה ל-3/6/12 תשלומים בעמדה או בקישור | E6: מאפשר מתנה גדולה יותר גם בתקציב מוגבל | F6: מגדיל סכום מתנה ממוצע ולכן את ROI | G6: בינונית | H6: גבוהה
B7: מתנות וסליקה | C7: ארנק מתנות דיגיטלי | D7: ריכוז כל המתנות בארנק אישי + העברה לחשבון/Bit אחרי האירוע | E7: שקיפות ושליטה מלאה בכספי המתנות | F7: - | G7: בינונית | H7: גבוהה
B8: מתנות וסליקה | C8: מתנה קבוצתית (Group Gift) | D8: כמה אורחים מתאחדים למתנה אחת גדולה (טיסה, מקרר וכו') | E8: חוויה ומתנה משמעותית | F8: בידול מול מתחרים | G8: בינונית | H8: בינונית
B9: מתנות וסליקה | C9: המרת מתנה לשובר/חוויה | D9: אפשרות לתת חוויה (ספא, מסעדה) במקום כסף | E9: גיוון והתאמה אישית | F9: שיתופי פעולה עם ספקים = הכנסה | G9: גבוהה | H9: נמוכה
B10: RSVP וחוויה | C10: אישור הגעה חכם + ניווט | D10: RSVP עם תזכורת, מפה, חניה ושיבוץ שולחן בלחיצה | E10: פחות בלבול ופחות שיחות | F10: פחות עומס בכניסה | G10: נמוכה | H10: גבוהה
B11: RSVP וחוויה | C11: Check-in בעמדה / QR בכניסה | D11: סריקת QR/זיהוי בכניסה שמעדכן הגעה בזמן אמת | E11: קבלת פנים חלקה | F11: דאטה מדויקת על נוכחות | G11: בינונית | H11: גבוהה
B12: RSVP וחוויה | C12: ספר ברכות דיגיטלי + וידאו | D12: אורח משאיר ברכה בכתב/וידאו בעמדה | E12: מזכרת רגשית | F12: תוכן שיווקי לאולם (באישור) | G12: בינונית | H12: בינונית
B13: RSVP וחוויה | C13: גלריית תמונות חיה | D13: העלאת תמונות אורחים למסך/אלבום משותף בזמן אמת | E13: חוויה משותפת | F13: תוכן ממותג לאולם | G13: בינונית | H13: בינונית
B14: דאטה ולידים | C14: CRM לידים חמים לאולם | D14: זיהוי אורחים פנויים/מאורסים → ליד לאולם (בהסכמה) | E14: - | F14: בידול מרכזי: לקוחות עתידיים | G14: גבוהה | H14: גבוהה
B15: דאטה ולידים | C15: דשבורד ROI לבעל אירוע | D15: דוח בזמן אמת: כמה מתנות, ממוצע, נוכחות | E15: שקיפות מלאה | F15: הוכחת ערך = חידוש חוזה | G15: בינונית | H15: גבוהה
B16: דאטה ולידים | C16: ניתוח אנונימי לאולם | D16: טרנדים: ממוצע מתנה לפי עונה/אזור/סוג אירוע | E16: - | F16: תמחור ותכנון מלאי חכם | G16: בינונית | H16: נמוכה
... B21: שיווק | C21: תוכנית הפניות (Referral) | D21: בעל אירוע מרוצה ממליץ → הנחה/קרדיט | E21: תמריץ כספי | F21: צמיחה אורגנית | G21: נמוכה | H21: בינונית

Sheet 🖥️ ממשק והרחבות
B2: ממשק משתמש לאולמות ואירועים + אפשרויות הרחבה
B3: מפרט חוויית משתמש לשלושה סוגי משתמשים, ואחריו מפת הרחבה לסוגי אירועים נוספים (דינרים, תערוכות, עמדת תצוגה).
B5: חלק א' — ממשק משתמש לפי סוג משתמש
B6: סוג משתמש | C6: מסך/ממשק | D6: יכולות עיקריות | E6: מטרת חוויה (UX)
B7: בעל האולם (אדמין) | C7: דשבורד ניהול אולם | D7: ניהול אירועים, יומן, חבילות, דוחות הכנסה, לידים, מיתוג White-Label | E7: שליטה מלאה + הוכחת ROI במבט אחד
B8: מנהל אירוע באולם | C8: מסך תפעול אירוע | D8: פתיחת אירוע בדקות, שיבוץ עמדה, סטטוס RSVP חי, צ'ק-אין | E8: תפעול מהיר ביום האירוע ללא הדרכה
B9: בעל האירוע (זוג/משפחה) | C9: אזור אישי לאירוע | D9: עריכת הזמנה, מעקב אישורי הגעה, סכום מתנות בזמן אמת, ייצוא דוח | E9: שקט נפשי ושקיפות — הכל במקום אחד
B10: האורח | C10: עמדה פיזית / קישור / QR | D10: מתנה באשראי/דיגיטלי, אישור הגעה, ברכה, ניווט ושיבוץ שולחן | E10: פעולה אחת פשוטה ב-30 שניות, ללא הורדה
B11: מנהל מערכת (שמחות פלוס) | C11: קונסול תפעול ארצי | D11: ניטור עמדות, סליקה, SLA, התראות תקלה, ניהול ספקים | E11: אמינות תפעולית ותמיכה פרואקטיבית
B13: חלק ב' — עקרונות עיצוב חוויה
B14: עיקרון | C14: יישום בפועל
B15: פשטות קיצונית לאורח | C15: ללא הרשמה/הורדה — מתנה ב-30 שניות, כפתור גדול אחד
B16: נגישות רב-דורית | C16: פונט גדול, ניגודיות, תמיכת קול/IVR למסלול כשר ומבוגרים
B17: מיתוג האולם בכל מסך | C17: לוגו, צבעים ותמונות האולם — כל אינטראקציה היא פרסום
B18: זמן אמת ושקיפות | C18: סכום מתנות, נוכחות ודוחות מתעדכנים חי לבעל האירוע ולאולם
B19: אפס נקודות כשל | C19: מצב Offline, גיבוי סלולרי וחשמל, תמיכת SLA ביום האירוע
B20: דאטה אחראית | C20: הסכמה מפורשת, פרטיות, וניהול לידים לפי חוק
B22: חלק ג' — אפשרויות הרחבה לסוגי אירועים
B23: סוג אירוע | C23: התאמת המוצר | D23: עמדת תצוגה/תרומה | E23: הזדמנות הכנסה | F23: עדיפות
B24: חתונות / בר-בת מצווה | C24: ליבת המוצר — מתנה+RSVP+עמדה | D24: עמדת מתנות אשראי בכניסה | E24: עמלת סליקה + דמי הקמה | F24: ליבה
B25: דינרים והתרמות (עמותות) | C25: מודול תרומה במקום מתנה + קבלה ל-46א' | D25: עמדת תרומה + מסך יעד התרמה חי | E25: עמלת סליקה + מנוי שנתי לעמותה | F25: גבוהה
B26: כנסים ותערוכות B2B | C26: עמדת תצוגה/לידים + תשלום כניסה/מוצר | D26: עמדת תצוגת מוצרים + Check-in מבקרים | E26: דמי הקמה לאירוע + עמלת מכירה | F26: בינונית
B27: אירועי חברה | C27: RSVP + סקרים + תשלום עובד אופציונלי | D27: עמדת מידע/הצבעה | E27: חבילת אירוע ארגוני | F27: בינונית
B28: ברית/אירוסין/חינה | C28: גרסה מוקטנת של חבילת השמחה | D28: עמדת מתנה קומפקטית | E28: דמי הקמה מופחתים | F28: בינונית
B29: אירועי מגזר חרדי | C29: מסלול כשר: IVR, ללא סמארטפון, הפרדה | D29: עמדות גברים/נשים נפרדות | E29: שותפות נדרים פלוס / נש"פ | F29: גבוהה
B31: הערה: כל הרחבה היא החלטת המשתמש — מודולרית וניתנת להפעלה/כיבוי לפי אולם וסוג אירוע.

Sheet 🧭 תוכנית עבודה
B2: תוכנית עבודה רב-שנתית | Roadmap תפעולי ומסחרי
B3: תוכנית לפי רבעונים, אבני דרך, אחראים ויעדי עמדות. יעד: נקודת איזון סביב 18 עמדות והתרחבות ל-450 עמדות ב-2031.
B5: תקופה | C5: תחום | D5: משימות מרכזיות | E5: אחראי | F5: יעד עמדות סוף תקופה | G5: KPI / אבן דרך
B6: Q1 2026 | C6: מוצר/תפעול | D6: פיילוט 5-10 עמדות, בדיקות סליקה, חוזה אולם ראשון, SLA תפעולי | E6: מנכ״ל + CTO | F6: 10 | G6: עמדה עובדת, 0 תקלות קריטיות, 3 אולמות בפיילוט
B7: Q2 2026 | C7: מכירות | D7: השקת חבילת אולם, דף נחיתה White Label, CRM לידים, 20 אולמות יעד | E7: מכירות | F7: 18 | G7: נקודת איזון תפעולית, 50 אירועים מצטברים
B8: Q3 2026 | C8: צמיחה | D8: הרחבת אזורי מרכז/שרון/ירושלים, גיוס נציג שטח, אוטומציית דוחות | E8: מכירות + Ops | F8: 20 | G8: 20 עמדות פעילות, NPS > 45
B9: Q4 2026 | C9: צמיחה | D9: הרחבת אזורי מרכז/שרון/ירושלים, גיוס נציג שטח, אוטומציית דוחות | E9: מכירות + Ops | F9: 20 | G9: 20 עמדות פעילות, NPS > 45
B10: Q1 2027 | C10: סקייל | D10: הרחבה ל-60 עמדות, חוזי מסגרת עם רשתות אולמות, שירות לקוחות 7/24 באירועים | E10: COO | F10: 60 | G10: EBITDA חיובי, 300 אירועים בשנה
B11: Q2 2027 | C11: סקייל | D11: הרחבה ל-60 עמדות, חוזי מסגרת עם רשתות אולמות, שירות לקוחות 7/24 באירועים | E11: COO | F11: 60 | G11: EBITDA חיובי, 300 אירועים בשנה
B12: Q3 2027 | C12: סקייל | D12: הרחבה ל-60 עמדות, חוזי מסגרת עם רשתות אולמות, שירות לקוחות 7/24 באירועים | E12: COO | F12: 60 | G12: EBITDA חיובי, 300 אירועים בשנה
B13: Q4 2027 | C13: סקייל | D13: הרחבה ל-60 עמדות, חוזי מסגרת עם רשתות אולמות, שירות לקוחות 7/24 באירועים | E13: COO | F13: 60 | G13: EBITDA חיובי, 300 אירועים בשנה
B14: Q1 2028 | C14: מוצר מתקדם | D14: מודול חרדי/IVR, שותף נדרים פלוס, דשבורד אולמות, API יצוא לידים | E14: CTO + שותפויות | F14: 120 | G14: 120 עמדות, 10 אולמות חרדיים
B15: Q2 2028 | C15: מוצר מתקדם | D15: מודול חרדי/IVR, שותף נדרים פלוס, דשבורד אולמות, API יצוא לידים | E15: CTO + שותפויות | F15: 120 | G15: 120 עמדות, 10 אולמות חרדיים
B16: Q3 2028 | C16: מוצר מתקדם | D16: מודול חרדי/IVR, שותף נדרים פלוס, דשבורד אולמות, API יצוא לידים | E16: CTO + שותפויות | F16: 120 | G16: 120 עמדות, 10 אולמות חרדיים
